2025-04-18 11:56:14,826 INFO: BookApp startup [in C:\Users\rakes\PycharmProjects\book_project\app\__init__.py:66]
2025-04-18 11:56:18,543 ERROR: Exception on / [GET] [in C:\Users\rakes\PycharmProjects\book_project\.venv\Lib\site-packages\flask\app.py:875]
Traceback (most recent call last):
  File "C:\Users\rakes\PycharmProjects\book_project\.venv\Lib\site-packages\flask\app.py", line 917, in full_dispatch_request
    rv = self.dispatch_request()
         ^^^^^^^^^^^^^^^^^^^^^^^
  File "C:\Users\rakes\PycharmProjects\book_project\.venv\Lib\site-packages\flask\app.py", line 891, in dispatch_request
    self.raise_routing_exception(req)
  File "C:\Users\rakes\PycharmProjects\book_project\.venv\Lib\site-packages\flask\app.py", line 500, in raise_routing_exception
    raise request.routing_exception  # type: ignore[misc]
    ^^^^^^^^^^^^^^^^^^^^^^^^^^^^^^^
  File "C:\Users\rakes\PycharmProjects\book_project\.venv\Lib\site-packages\flask\ctx.py", line 362, in match_request
    result = self.url_adapter.match(return_rule=True)  # type: ignore
             ^^^^^^^^^^^^^^^^^^^^^^^^^^^^^^^^^^^^^^^^
  File "C:\Users\rakes\PycharmProjects\book_project\.venv\Lib\site-packages\werkzeug\routing\map.py", line 629, in match
    raise NotFound() from None
werkzeug.exceptions.NotFound: 404 Not Found: The requested URL was not found on the server. If you entered the URL manually please check your spelling and try again.

During handling of the above exception, another exception occurred:

Traceback (most recent call last):
  File "C:\Users\rakes\PycharmProjects\book_project\.venv\Lib\site-packages\flask\app.py", line 1511, in wsgi_app
    response = self.full_dispatch_request()
               ^^^^^^^^^^^^^^^^^^^^^^^^^^^^
  File "C:\Users\rakes\PycharmProjects\book_project\.venv\Lib\site-packages\flask\app.py", line 919, in full_dispatch_request
    rv = self.handle_user_exception(e)
         ^^^^^^^^^^^^^^^^^^^^^^^^^^^^^
  File "C:\Users\rakes\PycharmProjects\book_project\.venv\Lib\site-packages\flask\app.py", line 802, in handle_user_exception
    return self.handle_http_exception(e)
           ^^^^^^^^^^^^^^^^^^^^^^^^^^^^^
  File "C:\Users\rakes\PycharmProjects\book_project\.venv\Lib\site-packages\flask\app.py", line 777, in handle_http_exception
    return self.ensure_sync(handler)(e)  # type: ignore[no-any-return]
           ^^^^^^^^^^^^^^^^^^^^^^^^^^^^
  File "C:\Users\rakes\PycharmProjects\book_project\app\__init__.py", line 48, in not_found_error
    return render_template('404.html'), 404
           ^^^^^^^^^^^^^^^^^^^^^^^^^^^
  File "C:\Users\rakes\PycharmProjects\book_project\.venv\Lib\site-packages\flask\templating.py", line 149, in render_template
    template = app.jinja_env.get_or_select_template(template_name_or_list)
               ^^^^^^^^^^^^^^^^^^^^^^^^^^^^^^^^^^^^^^^^^^^^^^^^^^^^^^^^^^^
  File "C:\Users\rakes\PycharmProjects\book_project\.venv\Lib\site-packages\jinja2\environment.py", line 1087, in get_or_select_template
    return self.get_template(template_name_or_list, parent, globals)
           ^^^^^^^^^^^^^^^^^^^^^^^^^^^^^^^^^^^^^^^^^^^^^^^^^^^^^^^^^
  File "C:\Users\rakes\PycharmProjects\book_project\.venv\Lib\site-packages\jinja2\environment.py", line 1016, in get_template
    return self._load_template(name, globals)
           ^^^^^^^^^^^^^^^^^^^^^^^^^^^^^^^^^^
  File "C:\Users\rakes\PycharmProjects\book_project\.venv\Lib\site-packages\jinja2\environment.py", line 975, in _load_template
    template = self.loader.load(self, name, self.make_globals(globals))
               ^^^^^^^^^^^^^^^^^^^^^^^^^^^^^^^^^^^^^^^^^^^^^^^^^^^^^^^^
  File "C:\Users\rakes\PycharmProjects\book_project\.venv\Lib\site-packages\jinja2\loaders.py", line 126, in load
    source, filename, uptodate = self.get_source(environment, name)
                                 ^^^^^^^^^^^^^^^^^^^^^^^^^^^^^^^^^^
  File "C:\Users\rakes\PycharmProjects\book_project\.venv\Lib\site-packages\flask\templating.py", line 65, in get_source
    return self._get_source_fast(environment, template)
           ^^^^^^^^^^^^^^^^^^^^^^^^^^^^^^^^^^^^^^^^^^^^
  File "C:\Users\rakes\PycharmProjects\book_project\.venv\Lib\site-packages\flask\templating.py", line 99, in _get_source_fast
    raise TemplateNotFound(template)
jinja2.exceptions.TemplateNotFound: 404.html
2025-04-18 11:58:19,357 INFO: BookApp startup [in C:\Users\rakes\PycharmProjects\book_project\app\__init__.py:66]
2025-04-18 11:58:21,573 ERROR: Exception on / [GET] [in C:\Users\rakes\PycharmProjects\book_project\.venv\Lib\site-packages\flask\app.py:875]
Traceback (most recent call last):
  File "C:\Users\rakes\PycharmProjects\book_project\.venv\Lib\site-packages\flask\app.py", line 917, in full_dispatch_request
    rv = self.dispatch_request()
         ^^^^^^^^^^^^^^^^^^^^^^^
  File "C:\Users\rakes\PycharmProjects\book_project\.venv\Lib\site-packages\flask\app.py", line 891, in dispatch_request
    self.raise_routing_exception(req)
  File "C:\Users\rakes\PycharmProjects\book_project\.venv\Lib\site-packages\flask\app.py", line 500, in raise_routing_exception
    raise request.routing_exception  # type: ignore[misc]
    ^^^^^^^^^^^^^^^^^^^^^^^^^^^^^^^
  File "C:\Users\rakes\PycharmProjects\book_project\.venv\Lib\site-packages\flask\ctx.py", line 362, in match_request
    result = self.url_adapter.match(return_rule=True)  # type: ignore
             ^^^^^^^^^^^^^^^^^^^^^^^^^^^^^^^^^^^^^^^^
  File "C:\Users\rakes\PycharmProjects\book_project\.venv\Lib\site-packages\werkzeug\routing\map.py", line 629, in match
    raise NotFound() from None
werkzeug.exceptions.NotFound: 404 Not Found: The requested URL was not found on the server. If you entered the URL manually please check your spelling and try again.

During handling of the above exception, another exception occurred:

Traceback (most recent call last):
  File "C:\Users\rakes\PycharmProjects\book_project\.venv\Lib\site-packages\sqlalchemy\engine\base.py", line 1964, in _exec_single_context
    self.dialect.do_execute(
  File "C:\Users\rakes\PycharmProjects\book_project\.venv\Lib\site-packages\sqlalchemy\engine\default.py", line 945, in do_execute
    cursor.execute(statement, parameters)
sqlite3.OperationalError: no such column: user.created_at

The above exception was the direct cause of the following exception:

Traceback (most recent call last):
  File "C:\Users\rakes\PycharmProjects\book_project\.venv\Lib\site-packages\flask\app.py", line 1511, in wsgi_app
    response = self.full_dispatch_request()
               ^^^^^^^^^^^^^^^^^^^^^^^^^^^^
  File "C:\Users\rakes\PycharmProjects\book_project\.venv\Lib\site-packages\flask\app.py", line 919, in full_dispatch_request
    rv = self.handle_user_exception(e)
         ^^^^^^^^^^^^^^^^^^^^^^^^^^^^^
  File "C:\Users\rakes\PycharmProjects\book_project\.venv\Lib\site-packages\flask\app.py", line 802, in handle_user_exception
    return self.handle_http_exception(e)
           ^^^^^^^^^^^^^^^^^^^^^^^^^^^^^
  File "C:\Users\rakes\PycharmProjects\book_project\.venv\Lib\site-packages\flask\app.py", line 777, in handle_http_exception
    return self.ensure_sync(handler)(e)  # type: ignore[no-any-return]
           ^^^^^^^^^^^^^^^^^^^^^^^^^^^^
  File "C:\Users\rakes\PycharmProjects\book_project\app\__init__.py", line 48, in not_found_error
    return render_template('404.html'), 404
           ^^^^^^^^^^^^^^^^^^^^^^^^^^^
  File "C:\Users\rakes\PycharmProjects\book_project\.venv\Lib\site-packages\flask\templating.py", line 150, in render_template
    return _render(app, template, context)
           ^^^^^^^^^^^^^^^^^^^^^^^^^^^^^^^
  File "C:\Users\rakes\PycharmProjects\book_project\.venv\Lib\site-packages\flask\templating.py", line 127, in _render
    app.update_template_context(context)
  File "C:\Users\rakes\PycharmProjects\book_project\.venv\Lib\site-packages\flask\app.py", line 530, in update_template_context
    context.update(self.ensure_sync(func)())
                   ^^^^^^^^^^^^^^^^^^^^^^^^
  File "C:\Users\rakes\PycharmProjects\book_project\.venv\Lib\site-packages\flask_login\utils.py", line 405, in _user_context_processor
    return dict(current_user=_get_user())
                             ^^^^^^^^^^^
  File "C:\Users\rakes\PycharmProjects\book_project\.venv\Lib\site-packages\flask_login\utils.py", line 370, in _get_user
    current_app.login_manager._load_user()
  File "C:\Users\rakes\PycharmProjects\book_project\.venv\Lib\site-packages\flask_login\login_manager.py", line 364, in _load_user
    user = self._user_callback(user_id)
           ^^^^^^^^^^^^^^^^^^^^^^^^^^^^
  File "C:\Users\rakes\PycharmProjects\book_project\app\__init__.py", line 43, in load_user
    return User.query.get(int(user_id))
           ^^^^^^^^^^^^^^^^^^^^^^^^^^^^
  File "<string>", line 2, in get
  File "C:\Users\rakes\PycharmProjects\book_project\.venv\Lib\site-packages\sqlalchemy\util\deprecations.py", line 386, in warned
    return fn(*args, **kwargs)  # type: ignore[no-any-return]
           ^^^^^^^^^^^^^^^^^^^
  File "C:\Users\rakes\PycharmProjects\book_project\.venv\Lib\site-packages\sqlalchemy\orm\query.py", line 1126, in get
    return self._get_impl(ident, loading.load_on_pk_identity)
           ^^^^^^^^^^^^^^^^^^^^^^^^^^^^^^^^^^^^^^^^^^^^^^^^^^
  File "C:\Users\rakes\PycharmProjects\book_project\.venv\Lib\site-packages\sqlalchemy\orm\query.py", line 1135, in _get_impl
    return self.session._get_impl(
           ^^^^^^^^^^^^^^^^^^^^^^^
  File "C:\Users\rakes\PycharmProjects\book_project\.venv\Lib\site-packages\sqlalchemy\orm\session.py", line 3874, in _get_impl
    return db_load_fn(
           ^^^^^^^^^^^
  File "C:\Users\rakes\PycharmProjects\book_project\.venv\Lib\site-packages\sqlalchemy\orm\loading.py", line 694, in load_on_pk_identity
    session.execute(
  File "C:\Users\rakes\PycharmProjects\book_project\.venv\Lib\site-packages\sqlalchemy\orm\session.py", line 2365, in execute
    return self._execute_internal(
           ^^^^^^^^^^^^^^^^^^^^^^^
  File "C:\Users\rakes\PycharmProjects\book_project\.venv\Lib\site-packages\sqlalchemy\orm\session.py", line 2251, in _execute_internal
    result: Result[Any] = compile_state_cls.orm_execute_statement(
                          ^^^^^^^^^^^^^^^^^^^^^^^^^^^^^^^^^^^^^^^^
  File "C:\Users\rakes\PycharmProjects\book_project\.venv\Lib\site-packages\sqlalchemy\orm\context.py", line 306, in orm_execute_statement
    result = conn.execute(
             ^^^^^^^^^^^^^
  File "C:\Users\rakes\PycharmProjects\book_project\.venv\Lib\site-packages\sqlalchemy\engine\base.py", line 1416, in execute
    return meth(
           ^^^^^
  File "C:\Users\rakes\PycharmProjects\book_project\.venv\Lib\site-packages\sqlalchemy\sql\elements.py", line 523, in _execute_on_connection
    return connection._execute_clauseelement(
           ^^^^^^^^^^^^^^^^^^^^^^^^^^^^^^^^^^
  File "C:\Users\rakes\PycharmProjects\book_project\.venv\Lib\site-packages\sqlalchemy\engine\base.py", line 1638, in _execute_clauseelement
    ret = self._execute_context(
          ^^^^^^^^^^^^^^^^^^^^^^
  File "C:\Users\rakes\PycharmProjects\book_project\.venv\Lib\site-packages\sqlalchemy\engine\base.py", line 1843, in _execute_context
    return self._exec_single_context(
           ^^^^^^^^^^^^^^^^^^^^^^^^^^
  File "C:\Users\rakes\PycharmProjects\book_project\.venv\Lib\site-packages\sqlalchemy\engine\base.py", line 1983, in _exec_single_context
    self._handle_dbapi_exception(
  File "C:\Users\rakes\PycharmProjects\book_project\.venv\Lib\site-packages\sqlalchemy\engine\base.py", line 2352, in _handle_dbapi_exception
    raise sqlalchemy_exception.with_traceback(exc_info[2]) from e
  File "C:\Users\rakes\PycharmProjects\book_project\.venv\Lib\site-packages\sqlalchemy\engine\base.py", line 1964, in _exec_single_context
    self.dialect.do_execute(
  File "C:\Users\rakes\PycharmProjects\book_project\.venv\Lib\site-packages\sqlalchemy\engine\default.py", line 945, in do_execute
    cursor.execute(statement, parameters)
sqlalchemy.exc.OperationalError: (sqlite3.OperationalError) no such column: user.created_at
[SQL: SELECT user.id AS user_id, user.username AS user_username, user.password_hash AS user_password_hash, user.is_admin AS user_is_admin, user.created_at AS user_created_at 
FROM user 
WHERE user.id = ?]
[parameters: (1,)]
(Background on this error at: https://sqlalche.me/e/20/e3q8)
2025-04-18 12:00:09,187 INFO: BookApp startup [in C:\Users\rakes\PycharmProjects\book_project\app\__init__.py:66]
2025-04-18 12:00:11,301 ERROR: Exception on / [GET] [in C:\Users\rakes\PycharmProjects\book_project\.venv\Lib\site-packages\flask\app.py:875]
Traceback (most recent call last):
  File "C:\Users\rakes\PycharmProjects\book_project\.venv\Lib\site-packages\flask\app.py", line 917, in full_dispatch_request
    rv = self.dispatch_request()
         ^^^^^^^^^^^^^^^^^^^^^^^
  File "C:\Users\rakes\PycharmProjects\book_project\.venv\Lib\site-packages\flask\app.py", line 891, in dispatch_request
    self.raise_routing_exception(req)
  File "C:\Users\rakes\PycharmProjects\book_project\.venv\Lib\site-packages\flask\app.py", line 500, in raise_routing_exception
    raise request.routing_exception  # type: ignore[misc]
    ^^^^^^^^^^^^^^^^^^^^^^^^^^^^^^^
  File "C:\Users\rakes\PycharmProjects\book_project\.venv\Lib\site-packages\flask\ctx.py", line 362, in match_request
    result = self.url_adapter.match(return_rule=True)  # type: ignore
             ^^^^^^^^^^^^^^^^^^^^^^^^^^^^^^^^^^^^^^^^
  File "C:\Users\rakes\PycharmProjects\book_project\.venv\Lib\site-packages\werkzeug\routing\map.py", line 629, in match
    raise NotFound() from None
werkzeug.exceptions.NotFound: 404 Not Found: The requested URL was not found on the server. If you entered the URL manually please check your spelling and try again.

During handling of the above exception, another exception occurred:

Traceback (most recent call last):
  File "C:\Users\rakes\PycharmProjects\book_project\.venv\Lib\site-packages\sqlalchemy\engine\base.py", line 1964, in _exec_single_context
    self.dialect.do_execute(
  File "C:\Users\rakes\PycharmProjects\book_project\.venv\Lib\site-packages\sqlalchemy\engine\default.py", line 945, in do_execute
    cursor.execute(statement, parameters)
sqlite3.OperationalError: no such column: user.created_at

The above exception was the direct cause of the following exception:

Traceback (most recent call last):
  File "C:\Users\rakes\PycharmProjects\book_project\.venv\Lib\site-packages\flask\app.py", line 1511, in wsgi_app
    response = self.full_dispatch_request()
               ^^^^^^^^^^^^^^^^^^^^^^^^^^^^
  File "C:\Users\rakes\PycharmProjects\book_project\.venv\Lib\site-packages\flask\app.py", line 919, in full_dispatch_request
    rv = self.handle_user_exception(e)
         ^^^^^^^^^^^^^^^^^^^^^^^^^^^^^
  File "C:\Users\rakes\PycharmProjects\book_project\.venv\Lib\site-packages\flask\app.py", line 802, in handle_user_exception
    return self.handle_http_exception(e)
           ^^^^^^^^^^^^^^^^^^^^^^^^^^^^^
  File "C:\Users\rakes\PycharmProjects\book_project\.venv\Lib\site-packages\flask\app.py", line 777, in handle_http_exception
    return self.ensure_sync(handler)(e)  # type: ignore[no-any-return]
           ^^^^^^^^^^^^^^^^^^^^^^^^^^^^
  File "C:\Users\rakes\PycharmProjects\book_project\app\__init__.py", line 48, in not_found_error
    return render_template('404.html'), 404
           ^^^^^^^^^^^^^^^^^^^^^^^^^^^
  File "C:\Users\rakes\PycharmProjects\book_project\.venv\Lib\site-packages\flask\templating.py", line 150, in render_template
    return _render(app, template, context)
           ^^^^^^^^^^^^^^^^^^^^^^^^^^^^^^^
  File "C:\Users\rakes\PycharmProjects\book_project\.venv\Lib\site-packages\flask\templating.py", line 127, in _render
    app.update_template_context(context)
  File "C:\Users\rakes\PycharmProjects\book_project\.venv\Lib\site-packages\flask\app.py", line 530, in update_template_context
    context.update(self.ensure_sync(func)())
                   ^^^^^^^^^^^^^^^^^^^^^^^^
  File "C:\Users\rakes\PycharmProjects\book_project\.venv\Lib\site-packages\flask_login\utils.py", line 405, in _user_context_processor
    return dict(current_user=_get_user())
                             ^^^^^^^^^^^
  File "C:\Users\rakes\PycharmProjects\book_project\.venv\Lib\site-packages\flask_login\utils.py", line 370, in _get_user
    current_app.login_manager._load_user()
  File "C:\Users\rakes\PycharmProjects\book_project\.venv\Lib\site-packages\flask_login\login_manager.py", line 364, in _load_user
    user = self._user_callback(user_id)
           ^^^^^^^^^^^^^^^^^^^^^^^^^^^^
  File "C:\Users\rakes\PycharmProjects\book_project\app\__init__.py", line 43, in load_user
    return User.query.get(int(user_id))
           ^^^^^^^^^^^^^^^^^^^^^^^^^^^^
  File "<string>", line 2, in get
  File "C:\Users\rakes\PycharmProjects\book_project\.venv\Lib\site-packages\sqlalchemy\util\deprecations.py", line 386, in warned
    return fn(*args, **kwargs)  # type: ignore[no-any-return]
           ^^^^^^^^^^^^^^^^^^^
  File "C:\Users\rakes\PycharmProjects\book_project\.venv\Lib\site-packages\sqlalchemy\orm\query.py", line 1126, in get
    return self._get_impl(ident, loading.load_on_pk_identity)
           ^^^^^^^^^^^^^^^^^^^^^^^^^^^^^^^^^^^^^^^^^^^^^^^^^^
  File "C:\Users\rakes\PycharmProjects\book_project\.venv\Lib\site-packages\sqlalchemy\orm\query.py", line 1135, in _get_impl
    return self.session._get_impl(
           ^^^^^^^^^^^^^^^^^^^^^^^
  File "C:\Users\rakes\PycharmProjects\book_project\.venv\Lib\site-packages\sqlalchemy\orm\session.py", line 3874, in _get_impl
    return db_load_fn(
           ^^^^^^^^^^^
  File "C:\Users\rakes\PycharmProjects\book_project\.venv\Lib\site-packages\sqlalchemy\orm\loading.py", line 694, in load_on_pk_identity
    session.execute(
  File "C:\Users\rakes\PycharmProjects\book_project\.venv\Lib\site-packages\sqlalchemy\orm\session.py", line 2365, in execute
    return self._execute_internal(
           ^^^^^^^^^^^^^^^^^^^^^^^
  File "C:\Users\rakes\PycharmProjects\book_project\.venv\Lib\site-packages\sqlalchemy\orm\session.py", line 2251, in _execute_internal
    result: Result[Any] = compile_state_cls.orm_execute_statement(
                          ^^^^^^^^^^^^^^^^^^^^^^^^^^^^^^^^^^^^^^^^
  File "C:\Users\rakes\PycharmProjects\book_project\.venv\Lib\site-packages\sqlalchemy\orm\context.py", line 306, in orm_execute_statement
    result = conn.execute(
             ^^^^^^^^^^^^^
  File "C:\Users\rakes\PycharmProjects\book_project\.venv\Lib\site-packages\sqlalchemy\engine\base.py", line 1416, in execute
    return meth(
           ^^^^^
  File "C:\Users\rakes\PycharmProjects\book_project\.venv\Lib\site-packages\sqlalchemy\sql\elements.py", line 523, in _execute_on_connection
    return connection._execute_clauseelement(
           ^^^^^^^^^^^^^^^^^^^^^^^^^^^^^^^^^^
  File "C:\Users\rakes\PycharmProjects\book_project\.venv\Lib\site-packages\sqlalchemy\engine\base.py", line 1638, in _execute_clauseelement
    ret = self._execute_context(
          ^^^^^^^^^^^^^^^^^^^^^^
  File "C:\Users\rakes\PycharmProjects\book_project\.venv\Lib\site-packages\sqlalchemy\engine\base.py", line 1843, in _execute_context
    return self._exec_single_context(
           ^^^^^^^^^^^^^^^^^^^^^^^^^^
  File "C:\Users\rakes\PycharmProjects\book_project\.venv\Lib\site-packages\sqlalchemy\engine\base.py", line 1983, in _exec_single_context
    self._handle_dbapi_exception(
  File "C:\Users\rakes\PycharmProjects\book_project\.venv\Lib\site-packages\sqlalchemy\engine\base.py", line 2352, in _handle_dbapi_exception
    raise sqlalchemy_exception.with_traceback(exc_info[2]) from e
  File "C:\Users\rakes\PycharmProjects\book_project\.venv\Lib\site-packages\sqlalchemy\engine\base.py", line 1964, in _exec_single_context
    self.dialect.do_execute(
  File "C:\Users\rakes\PycharmProjects\book_project\.venv\Lib\site-packages\sqlalchemy\engine\default.py", line 945, in do_execute
    cursor.execute(statement, parameters)
sqlalchemy.exc.OperationalError: (sqlite3.OperationalError) no such column: user.created_at
[SQL: SELECT user.id AS user_id, user.username AS user_username, user.password_hash AS user_password_hash, user.is_admin AS user_is_admin, user.created_at AS user_created_at 
FROM user 
WHERE user.id = ?]
[parameters: (1,)]
(Background on this error at: https://sqlalche.me/e/20/e3q8)
2025-04-18 12:08:24,538 INFO: BookApp startup [in C:\Users\rakes\PycharmProjects\book_project\app\__init__.py:66]
2025-04-18 12:08:27,435 ERROR: Exception on / [GET] [in C:\Users\rakes\PycharmProjects\book_project\.venv\Lib\site-packages\flask\app.py:875]
Traceback (most recent call last):
  File "C:\Users\rakes\PycharmProjects\book_project\.venv\Lib\site-packages\flask\app.py", line 917, in full_dispatch_request
    rv = self.dispatch_request()
         ^^^^^^^^^^^^^^^^^^^^^^^
  File "C:\Users\rakes\PycharmProjects\book_project\.venv\Lib\site-packages\flask\app.py", line 891, in dispatch_request
    self.raise_routing_exception(req)
  File "C:\Users\rakes\PycharmProjects\book_project\.venv\Lib\site-packages\flask\app.py", line 500, in raise_routing_exception
    raise request.routing_exception  # type: ignore[misc]
    ^^^^^^^^^^^^^^^^^^^^^^^^^^^^^^^
  File "C:\Users\rakes\PycharmProjects\book_project\.venv\Lib\site-packages\flask\ctx.py", line 362, in match_request
    result = self.url_adapter.match(return_rule=True)  # type: ignore
             ^^^^^^^^^^^^^^^^^^^^^^^^^^^^^^^^^^^^^^^^
  File "C:\Users\rakes\PycharmProjects\book_project\.venv\Lib\site-packages\werkzeug\routing\map.py", line 629, in match
    raise NotFound() from None
werkzeug.exceptions.NotFound: 404 Not Found: The requested URL was not found on the server. If you entered the URL manually please check your spelling and try again.

During handling of the above exception, another exception occurred:

Traceback (most recent call last):
  File "C:\Users\rakes\PycharmProjects\book_project\.venv\Lib\site-packages\sqlalchemy\engine\base.py", line 1964, in _exec_single_context
    self.dialect.do_execute(
  File "C:\Users\rakes\PycharmProjects\book_project\.venv\Lib\site-packages\sqlalchemy\engine\default.py", line 945, in do_execute
    cursor.execute(statement, parameters)
sqlite3.OperationalError: no such column: user.created_at

The above exception was the direct cause of the following exception:

Traceback (most recent call last):
  File "C:\Users\rakes\PycharmProjects\book_project\.venv\Lib\site-packages\flask\app.py", line 1511, in wsgi_app
    response = self.full_dispatch_request()
               ^^^^^^^^^^^^^^^^^^^^^^^^^^^^
  File "C:\Users\rakes\PycharmProjects\book_project\.venv\Lib\site-packages\flask\app.py", line 919, in full_dispatch_request
    rv = self.handle_user_exception(e)
         ^^^^^^^^^^^^^^^^^^^^^^^^^^^^^
  File "C:\Users\rakes\PycharmProjects\book_project\.venv\Lib\site-packages\flask\app.py", line 802, in handle_user_exception
    return self.handle_http_exception(e)
           ^^^^^^^^^^^^^^^^^^^^^^^^^^^^^
  File "C:\Users\rakes\PycharmProjects\book_project\.venv\Lib\site-packages\flask\app.py", line 777, in handle_http_exception
    return self.ensure_sync(handler)(e)  # type: ignore[no-any-return]
           ^^^^^^^^^^^^^^^^^^^^^^^^^^^^
  File "C:\Users\rakes\PycharmProjects\book_project\app\__init__.py", line 48, in not_found_error
    return render_template('404.html'), 404
           ^^^^^^^^^^^^^^^^^^^^^^^^^^^
  File "C:\Users\rakes\PycharmProjects\book_project\.venv\Lib\site-packages\flask\templating.py", line 150, in render_template
    return _render(app, template, context)
           ^^^^^^^^^^^^^^^^^^^^^^^^^^^^^^^
  File "C:\Users\rakes\PycharmProjects\book_project\.venv\Lib\site-packages\flask\templating.py", line 127, in _render
    app.update_template_context(context)
  File "C:\Users\rakes\PycharmProjects\book_project\.venv\Lib\site-packages\flask\app.py", line 530, in update_template_context
    context.update(self.ensure_sync(func)())
                   ^^^^^^^^^^^^^^^^^^^^^^^^
  File "C:\Users\rakes\PycharmProjects\book_project\.venv\Lib\site-packages\flask_login\utils.py", line 405, in _user_context_processor
    return dict(current_user=_get_user())
                             ^^^^^^^^^^^
  File "C:\Users\rakes\PycharmProjects\book_project\.venv\Lib\site-packages\flask_login\utils.py", line 370, in _get_user
    current_app.login_manager._load_user()
  File "C:\Users\rakes\PycharmProjects\book_project\.venv\Lib\site-packages\flask_login\login_manager.py", line 364, in _load_user
    user = self._user_callback(user_id)
           ^^^^^^^^^^^^^^^^^^^^^^^^^^^^
  File "C:\Users\rakes\PycharmProjects\book_project\app\__init__.py", line 43, in load_user
    return User.query.get(int(user_id))
           ^^^^^^^^^^^^^^^^^^^^^^^^^^^^
  File "<string>", line 2, in get
  File "C:\Users\rakes\PycharmProjects\book_project\.venv\Lib\site-packages\sqlalchemy\util\deprecations.py", line 386, in warned
    return fn(*args, **kwargs)  # type: ignore[no-any-return]
           ^^^^^^^^^^^^^^^^^^^
  File "C:\Users\rakes\PycharmProjects\book_project\.venv\Lib\site-packages\sqlalchemy\orm\query.py", line 1126, in get
    return self._get_impl(ident, loading.load_on_pk_identity)
           ^^^^^^^^^^^^^^^^^^^^^^^^^^^^^^^^^^^^^^^^^^^^^^^^^^
  File "C:\Users\rakes\PycharmProjects\book_project\.venv\Lib\site-packages\sqlalchemy\orm\query.py", line 1135, in _get_impl
    return self.session._get_impl(
           ^^^^^^^^^^^^^^^^^^^^^^^
  File "C:\Users\rakes\PycharmProjects\book_project\.venv\Lib\site-packages\sqlalchemy\orm\session.py", line 3874, in _get_impl
    return db_load_fn(
           ^^^^^^^^^^^
  File "C:\Users\rakes\PycharmProjects\book_project\.venv\Lib\site-packages\sqlalchemy\orm\loading.py", line 694, in load_on_pk_identity
    session.execute(
  File "C:\Users\rakes\PycharmProjects\book_project\.venv\Lib\site-packages\sqlalchemy\orm\session.py", line 2365, in execute
    return self._execute_internal(
           ^^^^^^^^^^^^^^^^^^^^^^^
  File "C:\Users\rakes\PycharmProjects\book_project\.venv\Lib\site-packages\sqlalchemy\orm\session.py", line 2251, in _execute_internal
    result: Result[Any] = compile_state_cls.orm_execute_statement(
                          ^^^^^^^^^^^^^^^^^^^^^^^^^^^^^^^^^^^^^^^^
  File "C:\Users\rakes\PycharmProjects\book_project\.venv\Lib\site-packages\sqlalchemy\orm\context.py", line 306, in orm_execute_statement
    result = conn.execute(
             ^^^^^^^^^^^^^
  File "C:\Users\rakes\PycharmProjects\book_project\.venv\Lib\site-packages\sqlalchemy\engine\base.py", line 1416, in execute
    return meth(
           ^^^^^
  File "C:\Users\rakes\PycharmProjects\book_project\.venv\Lib\site-packages\sqlalchemy\sql\elements.py", line 523, in _execute_on_connection
    return connection._execute_clauseelement(
           ^^^^^^^^^^^^^^^^^^^^^^^^^^^^^^^^^^
  File "C:\Users\rakes\PycharmProjects\book_project\.venv\Lib\site-packages\sqlalchemy\engine\base.py", line 1638, in _execute_clauseelement
    ret = self._execute_context(
          ^^^^^^^^^^^^^^^^^^^^^^
  File "C:\Users\rakes\PycharmProjects\book_project\.venv\Lib\site-packages\sqlalchemy\engine\base.py", line 1843, in _execute_context
    return self._exec_single_context(
           ^^^^^^^^^^^^^^^^^^^^^^^^^^
  File "C:\Users\rakes\PycharmProjects\book_project\.venv\Lib\site-packages\sqlalchemy\engine\base.py", line 1983, in _exec_single_context
    self._handle_dbapi_exception(
  File "C:\Users\rakes\PycharmProjects\book_project\.venv\Lib\site-packages\sqlalchemy\engine\base.py", line 2352, in _handle_dbapi_exception
    raise sqlalchemy_exception.with_traceback(exc_info[2]) from e
  File "C:\Users\rakes\PycharmProjects\book_project\.venv\Lib\site-packages\sqlalchemy\engine\base.py", line 1964, in _exec_single_context
    self.dialect.do_execute(
  File "C:\Users\rakes\PycharmProjects\book_project\.venv\Lib\site-packages\sqlalchemy\engine\default.py", line 945, in do_execute
    cursor.execute(statement, parameters)
sqlalchemy.exc.OperationalError: (sqlite3.OperationalError) no such column: user.created_at
[SQL: SELECT user.id AS user_id, user.username AS user_username, user.password_hash AS user_password_hash, user.is_admin AS user_is_admin, user.created_at AS user_created_at 
FROM user 
WHERE user.id = ?]
[parameters: (1,)]
(Background on this error at: https://sqlalche.me/e/20/e3q8)
2025-04-18 12:09:10,104 INFO: BookApp startup [in C:\Users\rakes\PycharmProjects\book_project\app\__init__.py:66]
2025-04-18 12:09:13,842 ERROR: Exception on / [GET] [in C:\Users\rakes\PycharmProjects\book_project\.venv\Lib\site-packages\flask\app.py:875]
Traceback (most recent call last):
  File "C:\Users\rakes\PycharmProjects\book_project\.venv\Lib\site-packages\flask\app.py", line 917, in full_dispatch_request
    rv = self.dispatch_request()
         ^^^^^^^^^^^^^^^^^^^^^^^
  File "C:\Users\rakes\PycharmProjects\book_project\.venv\Lib\site-packages\flask\app.py", line 891, in dispatch_request
    self.raise_routing_exception(req)
  File "C:\Users\rakes\PycharmProjects\book_project\.venv\Lib\site-packages\flask\app.py", line 500, in raise_routing_exception
    raise request.routing_exception  # type: ignore[misc]
    ^^^^^^^^^^^^^^^^^^^^^^^^^^^^^^^
  File "C:\Users\rakes\PycharmProjects\book_project\.venv\Lib\site-packages\flask\ctx.py", line 362, in match_request
    result = self.url_adapter.match(return_rule=True)  # type: ignore
             ^^^^^^^^^^^^^^^^^^^^^^^^^^^^^^^^^^^^^^^^
  File "C:\Users\rakes\PycharmProjects\book_project\.venv\Lib\site-packages\werkzeug\routing\map.py", line 629, in match
    raise NotFound() from None
werkzeug.exceptions.NotFound: 404 Not Found: The requested URL was not found on the server. If you entered the URL manually please check your spelling and try again.

During handling of the above exception, another exception occurred:

Traceback (most recent call last):
  File "C:\Users\rakes\PycharmProjects\book_project\.venv\Lib\site-packages\sqlalchemy\engine\base.py", line 1964, in _exec_single_context
    self.dialect.do_execute(
  File "C:\Users\rakes\PycharmProjects\book_project\.venv\Lib\site-packages\sqlalchemy\engine\default.py", line 945, in do_execute
    cursor.execute(statement, parameters)
sqlite3.OperationalError: no such column: user.created_at

The above exception was the direct cause of the following exception:

Traceback (most recent call last):
  File "C:\Users\rakes\PycharmProjects\book_project\.venv\Lib\site-packages\flask\app.py", line 1511, in wsgi_app
    response = self.full_dispatch_request()
               ^^^^^^^^^^^^^^^^^^^^^^^^^^^^
  File "C:\Users\rakes\PycharmProjects\book_project\.venv\Lib\site-packages\flask\app.py", line 919, in full_dispatch_request
    rv = self.handle_user_exception(e)
         ^^^^^^^^^^^^^^^^^^^^^^^^^^^^^
  File "C:\Users\rakes\PycharmProjects\book_project\.venv\Lib\site-packages\flask\app.py", line 802, in handle_user_exception
    return self.handle_http_exception(e)
           ^^^^^^^^^^^^^^^^^^^^^^^^^^^^^
  File "C:\Users\rakes\PycharmProjects\book_project\.venv\Lib\site-packages\flask\app.py", line 777, in handle_http_exception
    return self.ensure_sync(handler)(e)  # type: ignore[no-any-return]
           ^^^^^^^^^^^^^^^^^^^^^^^^^^^^
  File "C:\Users\rakes\PycharmProjects\book_project\app\__init__.py", line 48, in not_found_error
    return render_template('404.html'), 404
           ^^^^^^^^^^^^^^^^^^^^^^^^^^^
  File "C:\Users\rakes\PycharmProjects\book_project\.venv\Lib\site-packages\flask\templating.py", line 150, in render_template
    return _render(app, template, context)
           ^^^^^^^^^^^^^^^^^^^^^^^^^^^^^^^
  File "C:\Users\rakes\PycharmProjects\book_project\.venv\Lib\site-packages\flask\templating.py", line 127, in _render
    app.update_template_context(context)
  File "C:\Users\rakes\PycharmProjects\book_project\.venv\Lib\site-packages\flask\app.py", line 530, in update_template_context
    context.update(self.ensure_sync(func)())
                   ^^^^^^^^^^^^^^^^^^^^^^^^
  File "C:\Users\rakes\PycharmProjects\book_project\.venv\Lib\site-packages\flask_login\utils.py", line 405, in _user_context_processor
    return dict(current_user=_get_user())
                             ^^^^^^^^^^^
  File "C:\Users\rakes\PycharmProjects\book_project\.venv\Lib\site-packages\flask_login\utils.py", line 370, in _get_user
    current_app.login_manager._load_user()
  File "C:\Users\rakes\PycharmProjects\book_project\.venv\Lib\site-packages\flask_login\login_manager.py", line 364, in _load_user
    user = self._user_callback(user_id)
           ^^^^^^^^^^^^^^^^^^^^^^^^^^^^
  File "C:\Users\rakes\PycharmProjects\book_project\app\__init__.py", line 43, in load_user
    return User.query.get(int(user_id))
           ^^^^^^^^^^^^^^^^^^^^^^^^^^^^
  File "<string>", line 2, in get
  File "C:\Users\rakes\PycharmProjects\book_project\.venv\Lib\site-packages\sqlalchemy\util\deprecations.py", line 386, in warned
    return fn(*args, **kwargs)  # type: ignore[no-any-return]
           ^^^^^^^^^^^^^^^^^^^
  File "C:\Users\rakes\PycharmProjects\book_project\.venv\Lib\site-packages\sqlalchemy\orm\query.py", line 1126, in get
    return self._get_impl(ident, loading.load_on_pk_identity)
           ^^^^^^^^^^^^^^^^^^^^^^^^^^^^^^^^^^^^^^^^^^^^^^^^^^
  File "C:\Users\rakes\PycharmProjects\book_project\.venv\Lib\site-packages\sqlalchemy\orm\query.py", line 1135, in _get_impl
    return self.session._get_impl(
           ^^^^^^^^^^^^^^^^^^^^^^^
  File "C:\Users\rakes\PycharmProjects\book_project\.venv\Lib\site-packages\sqlalchemy\orm\session.py", line 3874, in _get_impl
    return db_load_fn(
           ^^^^^^^^^^^
  File "C:\Users\rakes\PycharmProjects\book_project\.venv\Lib\site-packages\sqlalchemy\orm\loading.py", line 694, in load_on_pk_identity
    session.execute(
  File "C:\Users\rakes\PycharmProjects\book_project\.venv\Lib\site-packages\sqlalchemy\orm\session.py", line 2365, in execute
    return self._execute_internal(
           ^^^^^^^^^^^^^^^^^^^^^^^
  File "C:\Users\rakes\PycharmProjects\book_project\.venv\Lib\site-packages\sqlalchemy\orm\session.py", line 2251, in _execute_internal
    result: Result[Any] = compile_state_cls.orm_execute_statement(
                          ^^^^^^^^^^^^^^^^^^^^^^^^^^^^^^^^^^^^^^^^
  File "C:\Users\rakes\PycharmProjects\book_project\.venv\Lib\site-packages\sqlalchemy\orm\context.py", line 306, in orm_execute_statement
    result = conn.execute(
             ^^^^^^^^^^^^^
  File "C:\Users\rakes\PycharmProjects\book_project\.venv\Lib\site-packages\sqlalchemy\engine\base.py", line 1416, in execute
    return meth(
           ^^^^^
  File "C:\Users\rakes\PycharmProjects\book_project\.venv\Lib\site-packages\sqlalchemy\sql\elements.py", line 523, in _execute_on_connection
    return connection._execute_clauseelement(
           ^^^^^^^^^^^^^^^^^^^^^^^^^^^^^^^^^^
  File "C:\Users\rakes\PycharmProjects\book_project\.venv\Lib\site-packages\sqlalchemy\engine\base.py", line 1638, in _execute_clauseelement
    ret = self._execute_context(
          ^^^^^^^^^^^^^^^^^^^^^^
  File "C:\Users\rakes\PycharmProjects\book_project\.venv\Lib\site-packages\sqlalchemy\engine\base.py", line 1843, in _execute_context
    return self._exec_single_context(
           ^^^^^^^^^^^^^^^^^^^^^^^^^^
  File "C:\Users\rakes\PycharmProjects\book_project\.venv\Lib\site-packages\sqlalchemy\engine\base.py", line 1983, in _exec_single_context
    self._handle_dbapi_exception(
  File "C:\Users\rakes\PycharmProjects\book_project\.venv\Lib\site-packages\sqlalchemy\engine\base.py", line 2352, in _handle_dbapi_exception
    raise sqlalchemy_exception.with_traceback(exc_info[2]) from e
  File "C:\Users\rakes\PycharmProjects\book_project\.venv\Lib\site-packages\sqlalchemy\engine\base.py", line 1964, in _exec_single_context
    self.dialect.do_execute(
  File "C:\Users\rakes\PycharmProjects\book_project\.venv\Lib\site-packages\sqlalchemy\engine\default.py", line 945, in do_execute
    cursor.execute(statement, parameters)
sqlalchemy.exc.OperationalError: (sqlite3.OperationalError) no such column: user.created_at
[SQL: SELECT user.id AS user_id, user.username AS user_username, user.password_hash AS user_password_hash, user.is_admin AS user_is_admin, user.created_at AS user_created_at 
FROM user 
WHERE user.id = ?]
[parameters: (1,)]
(Background on this error at: https://sqlalche.me/e/20/e3q8)
2025-04-18 12:11:39,970 INFO: BookApp startup [in C:\Users\rakes\PycharmProjects\book_project\app\__init__.py:66]
2025-04-18 12:15:35,910 INFO: BookApp startup [in C:\Users\rakes\PycharmProjects\book_project\app\__init__.py:66]
2025-04-18 12:15:37,789 ERROR: Exception on / [GET] [in C:\Users\rakes\PycharmProjects\book_project\.venv\Lib\site-packages\flask\app.py:875]
Traceback (most recent call last):
  File "C:\Users\rakes\PycharmProjects\book_project\.venv\Lib\site-packages\flask\app.py", line 917, in full_dispatch_request
    rv = self.dispatch_request()
         ^^^^^^^^^^^^^^^^^^^^^^^
  File "C:\Users\rakes\PycharmProjects\book_project\.venv\Lib\site-packages\flask\app.py", line 891, in dispatch_request
    self.raise_routing_exception(req)
  File "C:\Users\rakes\PycharmProjects\book_project\.venv\Lib\site-packages\flask\app.py", line 500, in raise_routing_exception
    raise request.routing_exception  # type: ignore[misc]
    ^^^^^^^^^^^^^^^^^^^^^^^^^^^^^^^
  File "C:\Users\rakes\PycharmProjects\book_project\.venv\Lib\site-packages\flask\ctx.py", line 362, in match_request
    result = self.url_adapter.match(return_rule=True)  # type: ignore
             ^^^^^^^^^^^^^^^^^^^^^^^^^^^^^^^^^^^^^^^^
  File "C:\Users\rakes\PycharmProjects\book_project\.venv\Lib\site-packages\werkzeug\routing\map.py", line 629, in match
    raise NotFound() from None
werkzeug.exceptions.NotFound: 404 Not Found: The requested URL was not found on the server. If you entered the URL manually please check your spelling and try again.

During handling of the above exception, another exception occurred:

Traceback (most recent call last):
  File "C:\Users\rakes\PycharmProjects\book_project\.venv\Lib\site-packages\sqlalchemy\engine\base.py", line 1964, in _exec_single_context
    self.dialect.do_execute(
  File "C:\Users\rakes\PycharmProjects\book_project\.venv\Lib\site-packages\sqlalchemy\engine\default.py", line 945, in do_execute
    cursor.execute(statement, parameters)
sqlite3.OperationalError: no such column: user.created_at

The above exception was the direct cause of the following exception:

Traceback (most recent call last):
  File "C:\Users\rakes\PycharmProjects\book_project\.venv\Lib\site-packages\flask\app.py", line 1511, in wsgi_app
    response = self.full_dispatch_request()
               ^^^^^^^^^^^^^^^^^^^^^^^^^^^^
  File "C:\Users\rakes\PycharmProjects\book_project\.venv\Lib\site-packages\flask\app.py", line 919, in full_dispatch_request
    rv = self.handle_user_exception(e)
         ^^^^^^^^^^^^^^^^^^^^^^^^^^^^^
  File "C:\Users\rakes\PycharmProjects\book_project\.venv\Lib\site-packages\flask\app.py", line 802, in handle_user_exception
    return self.handle_http_exception(e)
           ^^^^^^^^^^^^^^^^^^^^^^^^^^^^^
  File "C:\Users\rakes\PycharmProjects\book_project\.venv\Lib\site-packages\flask\app.py", line 777, in handle_http_exception
    return self.ensure_sync(handler)(e)  # type: ignore[no-any-return]
           ^^^^^^^^^^^^^^^^^^^^^^^^^^^^
  File "C:\Users\rakes\PycharmProjects\book_project\app\__init__.py", line 48, in not_found_error
    return render_template('404.html'), 404
           ^^^^^^^^^^^^^^^^^^^^^^^^^^^
  File "C:\Users\rakes\PycharmProjects\book_project\.venv\Lib\site-packages\flask\templating.py", line 150, in render_template
    return _render(app, template, context)
           ^^^^^^^^^^^^^^^^^^^^^^^^^^^^^^^
  File "C:\Users\rakes\PycharmProjects\book_project\.venv\Lib\site-packages\flask\templating.py", line 127, in _render
    app.update_template_context(context)
  File "C:\Users\rakes\PycharmProjects\book_project\.venv\Lib\site-packages\flask\app.py", line 530, in update_template_context
    context.update(self.ensure_sync(func)())
                   ^^^^^^^^^^^^^^^^^^^^^^^^
  File "C:\Users\rakes\PycharmProjects\book_project\.venv\Lib\site-packages\flask_login\utils.py", line 405, in _user_context_processor
    return dict(current_user=_get_user())
                             ^^^^^^^^^^^
  File "C:\Users\rakes\PycharmProjects\book_project\.venv\Lib\site-packages\flask_login\utils.py", line 370, in _get_user
    current_app.login_manager._load_user()
  File "C:\Users\rakes\PycharmProjects\book_project\.venv\Lib\site-packages\flask_login\login_manager.py", line 364, in _load_user
    user = self._user_callback(user_id)
           ^^^^^^^^^^^^^^^^^^^^^^^^^^^^
  File "C:\Users\rakes\PycharmProjects\book_project\app\__init__.py", line 43, in load_user
    return User.query.get(int(user_id))
           ^^^^^^^^^^^^^^^^^^^^^^^^^^^^
  File "<string>", line 2, in get
  File "C:\Users\rakes\PycharmProjects\book_project\.venv\Lib\site-packages\sqlalchemy\util\deprecations.py", line 386, in warned
    return fn(*args, **kwargs)  # type: ignore[no-any-return]
           ^^^^^^^^^^^^^^^^^^^
  File "C:\Users\rakes\PycharmProjects\book_project\.venv\Lib\site-packages\sqlalchemy\orm\query.py", line 1126, in get
    return self._get_impl(ident, loading.load_on_pk_identity)
           ^^^^^^^^^^^^^^^^^^^^^^^^^^^^^^^^^^^^^^^^^^^^^^^^^^
  File "C:\Users\rakes\PycharmProjects\book_project\.venv\Lib\site-packages\sqlalchemy\orm\query.py", line 1135, in _get_impl
    return self.session._get_impl(
           ^^^^^^^^^^^^^^^^^^^^^^^
  File "C:\Users\rakes\PycharmProjects\book_project\.venv\Lib\site-packages\sqlalchemy\orm\session.py", line 3874, in _get_impl
    return db_load_fn(
           ^^^^^^^^^^^
  File "C:\Users\rakes\PycharmProjects\book_project\.venv\Lib\site-packages\sqlalchemy\orm\loading.py", line 694, in load_on_pk_identity
    session.execute(
  File "C:\Users\rakes\PycharmProjects\book_project\.venv\Lib\site-packages\sqlalchemy\orm\session.py", line 2365, in execute
    return self._execute_internal(
           ^^^^^^^^^^^^^^^^^^^^^^^
  File "C:\Users\rakes\PycharmProjects\book_project\.venv\Lib\site-packages\sqlalchemy\orm\session.py", line 2251, in _execute_internal
    result: Result[Any] = compile_state_cls.orm_execute_statement(
                          ^^^^^^^^^^^^^^^^^^^^^^^^^^^^^^^^^^^^^^^^
  File "C:\Users\rakes\PycharmProjects\book_project\.venv\Lib\site-packages\sqlalchemy\orm\context.py", line 306, in orm_execute_statement
    result = conn.execute(
             ^^^^^^^^^^^^^
  File "C:\Users\rakes\PycharmProjects\book_project\.venv\Lib\site-packages\sqlalchemy\engine\base.py", line 1416, in execute
    return meth(
           ^^^^^
  File "C:\Users\rakes\PycharmProjects\book_project\.venv\Lib\site-packages\sqlalchemy\sql\elements.py", line 523, in _execute_on_connection
    return connection._execute_clauseelement(
           ^^^^^^^^^^^^^^^^^^^^^^^^^^^^^^^^^^
  File "C:\Users\rakes\PycharmProjects\book_project\.venv\Lib\site-packages\sqlalchemy\engine\base.py", line 1638, in _execute_clauseelement
    ret = self._execute_context(
          ^^^^^^^^^^^^^^^^^^^^^^
  File "C:\Users\rakes\PycharmProjects\book_project\.venv\Lib\site-packages\sqlalchemy\engine\base.py", line 1843, in _execute_context
    return self._exec_single_context(
           ^^^^^^^^^^^^^^^^^^^^^^^^^^
  File "C:\Users\rakes\PycharmProjects\book_project\.venv\Lib\site-packages\sqlalchemy\engine\base.py", line 1983, in _exec_single_context
    self._handle_dbapi_exception(
  File "C:\Users\rakes\PycharmProjects\book_project\.venv\Lib\site-packages\sqlalchemy\engine\base.py", line 2352, in _handle_dbapi_exception
    raise sqlalchemy_exception.with_traceback(exc_info[2]) from e
  File "C:\Users\rakes\PycharmProjects\book_project\.venv\Lib\site-packages\sqlalchemy\engine\base.py", line 1964, in _exec_single_context
    self.dialect.do_execute(
  File "C:\Users\rakes\PycharmProjects\book_project\.venv\Lib\site-packages\sqlalchemy\engine\default.py", line 945, in do_execute
    cursor.execute(statement, parameters)
sqlalchemy.exc.OperationalError: (sqlite3.OperationalError) no such column: user.created_at
[SQL: SELECT user.id AS user_id, user.username AS user_username, user.password_hash AS user_password_hash, user.is_admin AS user_is_admin, user.created_at AS user_created_at 
FROM user 
WHERE user.id = ?]
[parameters: (1,)]
(Background on this error at: https://sqlalche.me/e/20/e3q8)
2025-04-18 14:02:41,664 INFO: BookApp startup [in C:\Users\rakes\PycharmProjects\book_project\app\__init__.py:69]
2025-04-18 14:02:44,634 ERROR: Exception on / [GET] [in C:\Users\rakes\PycharmProjects\book_project\.venv\Lib\site-packages\flask\app.py:875]
Traceback (most recent call last):
  File "C:\Users\rakes\PycharmProjects\book_project\.venv\Lib\site-packages\flask\app.py", line 917, in full_dispatch_request
    rv = self.dispatch_request()
         ^^^^^^^^^^^^^^^^^^^^^^^
  File "C:\Users\rakes\PycharmProjects\book_project\.venv\Lib\site-packages\flask\app.py", line 891, in dispatch_request
    self.raise_routing_exception(req)
  File "C:\Users\rakes\PycharmProjects\book_project\.venv\Lib\site-packages\flask\app.py", line 500, in raise_routing_exception
    raise request.routing_exception  # type: ignore[misc]
    ^^^^^^^^^^^^^^^^^^^^^^^^^^^^^^^
  File "C:\Users\rakes\PycharmProjects\book_project\.venv\Lib\site-packages\flask\ctx.py", line 362, in match_request
    result = self.url_adapter.match(return_rule=True)  # type: ignore
             ^^^^^^^^^^^^^^^^^^^^^^^^^^^^^^^^^^^^^^^^
  File "C:\Users\rakes\PycharmProjects\book_project\.venv\Lib\site-packages\werkzeug\routing\map.py", line 629, in match
    raise NotFound() from None
werkzeug.exceptions.NotFound: 404 Not Found: The requested URL was not found on the server. If you entered the URL manually please check your spelling and try again.

During handling of the above exception, another exception occurred:

Traceback (most recent call last):
  File "C:\Users\rakes\PycharmProjects\book_project\.venv\Lib\site-packages\sqlalchemy\engine\base.py", line 1964, in _exec_single_context
    self.dialect.do_execute(
  File "C:\Users\rakes\PycharmProjects\book_project\.venv\Lib\site-packages\sqlalchemy\engine\default.py", line 945, in do_execute
    cursor.execute(statement, parameters)
sqlite3.OperationalError: no such column: user.created_at

The above exception was the direct cause of the following exception:

Traceback (most recent call last):
  File "C:\Users\rakes\PycharmProjects\book_project\.venv\Lib\site-packages\flask\app.py", line 1511, in wsgi_app
    response = self.full_dispatch_request()
               ^^^^^^^^^^^^^^^^^^^^^^^^^^^^
  File "C:\Users\rakes\PycharmProjects\book_project\.venv\Lib\site-packages\flask\app.py", line 919, in full_dispatch_request
    rv = self.handle_user_exception(e)
         ^^^^^^^^^^^^^^^^^^^^^^^^^^^^^
  File "C:\Users\rakes\PycharmProjects\book_project\.venv\Lib\site-packages\flask\app.py", line 802, in handle_user_exception
    return self.handle_http_exception(e)
           ^^^^^^^^^^^^^^^^^^^^^^^^^^^^^
  File "C:\Users\rakes\PycharmProjects\book_project\.venv\Lib\site-packages\flask\app.py", line 777, in handle_http_exception
    return self.ensure_sync(handler)(e)  # type: ignore[no-any-return]
           ^^^^^^^^^^^^^^^^^^^^^^^^^^^^
  File "C:\Users\rakes\PycharmProjects\book_project\app\__init__.py", line 51, in not_found_error
    return render_template('404.html'), 404
           ^^^^^^^^^^^^^^^^^^^^^^^^^^^
  File "C:\Users\rakes\PycharmProjects\book_project\.venv\Lib\site-packages\flask\templating.py", line 150, in render_template
    return _render(app, template, context)
           ^^^^^^^^^^^^^^^^^^^^^^^^^^^^^^^
  File "C:\Users\rakes\PycharmProjects\book_project\.venv\Lib\site-packages\flask\templating.py", line 127, in _render
    app.update_template_context(context)
  File "C:\Users\rakes\PycharmProjects\book_project\.venv\Lib\site-packages\flask\app.py", line 530, in update_template_context
    context.update(self.ensure_sync(func)())
                   ^^^^^^^^^^^^^^^^^^^^^^^^
  File "C:\Users\rakes\PycharmProjects\book_project\.venv\Lib\site-packages\flask_login\utils.py", line 405, in _user_context_processor
    return dict(current_user=_get_user())
                             ^^^^^^^^^^^
  File "C:\Users\rakes\PycharmProjects\book_project\.venv\Lib\site-packages\flask_login\utils.py", line 370, in _get_user
    current_app.login_manager._load_user()
  File "C:\Users\rakes\PycharmProjects\book_project\.venv\Lib\site-packages\flask_login\login_manager.py", line 364, in _load_user
    user = self._user_callback(user_id)
           ^^^^^^^^^^^^^^^^^^^^^^^^^^^^
  File "C:\Users\rakes\PycharmProjects\book_project\app\__init__.py", line 46, in load_user
    return User.query.get(int(user_id))
           ^^^^^^^^^^^^^^^^^^^^^^^^^^^^
  File "<string>", line 2, in get
  File "C:\Users\rakes\PycharmProjects\book_project\.venv\Lib\site-packages\sqlalchemy\util\deprecations.py", line 386, in warned
    return fn(*args, **kwargs)  # type: ignore[no-any-return]
           ^^^^^^^^^^^^^^^^^^^
  File "C:\Users\rakes\PycharmProjects\book_project\.venv\Lib\site-packages\sqlalchemy\orm\query.py", line 1126, in get
    return self._get_impl(ident, loading.load_on_pk_identity)
           ^^^^^^^^^^^^^^^^^^^^^^^^^^^^^^^^^^^^^^^^^^^^^^^^^^
  File "C:\Users\rakes\PycharmProjects\book_project\.venv\Lib\site-packages\sqlalchemy\orm\query.py", line 1135, in _get_impl
    return self.session._get_impl(
           ^^^^^^^^^^^^^^^^^^^^^^^
  File "C:\Users\rakes\PycharmProjects\book_project\.venv\Lib\site-packages\sqlalchemy\orm\session.py", line 3874, in _get_impl
    return db_load_fn(
           ^^^^^^^^^^^
  File "C:\Users\rakes\PycharmProjects\book_project\.venv\Lib\site-packages\sqlalchemy\orm\loading.py", line 694, in load_on_pk_identity
    session.execute(
  File "C:\Users\rakes\PycharmProjects\book_project\.venv\Lib\site-packages\sqlalchemy\orm\session.py", line 2365, in execute
    return self._execute_internal(
           ^^^^^^^^^^^^^^^^^^^^^^^
  File "C:\Users\rakes\PycharmProjects\book_project\.venv\Lib\site-packages\sqlalchemy\orm\session.py", line 2251, in _execute_internal
    result: Result[Any] = compile_state_cls.orm_execute_statement(
                          ^^^^^^^^^^^^^^^^^^^^^^^^^^^^^^^^^^^^^^^^
  File "C:\Users\rakes\PycharmProjects\book_project\.venv\Lib\site-packages\sqlalchemy\orm\context.py", line 306, in orm_execute_statement
    result = conn.execute(
             ^^^^^^^^^^^^^
  File "C:\Users\rakes\PycharmProjects\book_project\.venv\Lib\site-packages\sqlalchemy\engine\base.py", line 1416, in execute
    return meth(
           ^^^^^
  File "C:\Users\rakes\PycharmProjects\book_project\.venv\Lib\site-packages\sqlalchemy\sql\elements.py", line 523, in _execute_on_connection
    return connection._execute_clauseelement(
           ^^^^^^^^^^^^^^^^^^^^^^^^^^^^^^^^^^
  File "C:\Users\rakes\PycharmProjects\book_project\.venv\Lib\site-packages\sqlalchemy\engine\base.py", line 1638, in _execute_clauseelement
    ret = self._execute_context(
          ^^^^^^^^^^^^^^^^^^^^^^
  File "C:\Users\rakes\PycharmProjects\book_project\.venv\Lib\site-packages\sqlalchemy\engine\base.py", line 1843, in _execute_context
    return self._exec_single_context(
           ^^^^^^^^^^^^^^^^^^^^^^^^^^
  File "C:\Users\rakes\PycharmProjects\book_project\.venv\Lib\site-packages\sqlalchemy\engine\base.py", line 1983, in _exec_single_context
    self._handle_dbapi_exception(
  File "C:\Users\rakes\PycharmProjects\book_project\.venv\Lib\site-packages\sqlalchemy\engine\base.py", line 2352, in _handle_dbapi_exception
    raise sqlalchemy_exception.with_traceback(exc_info[2]) from e
  File "C:\Users\rakes\PycharmProjects\book_project\.venv\Lib\site-packages\sqlalchemy\engine\base.py", line 1964, in _exec_single_context
    self.dialect.do_execute(
  File "C:\Users\rakes\PycharmProjects\book_project\.venv\Lib\site-packages\sqlalchemy\engine\default.py", line 945, in do_execute
    cursor.execute(statement, parameters)
sqlalchemy.exc.OperationalError: (sqlite3.OperationalError) no such column: user.created_at
[SQL: SELECT user.id AS user_id, user.username AS user_username, user.password_hash AS user_password_hash, user.is_admin AS user_is_admin, user.created_at AS user_created_at 
FROM user 
WHERE user.id = ?]
[parameters: (1,)]
(Background on this error at: https://sqlalche.me/e/20/e3q8)
2025-04-18 14:06:59,643 INFO: BookApp startup [in C:\Users\rakes\PycharmProjects\book_project\app\__init__.py:69]
2025-04-18 14:07:08,928 INFO: BookApp startup [in C:\Users\rakes\PycharmProjects\book_project\app\__init__.py:69]
2025-04-18 14:07:21,995 INFO: BookApp startup [in C:\Users\rakes\PycharmProjects\book_project\app\__init__.py:69]
2025-04-18 14:07:43,539 INFO: BookApp startup [in C:\Users\rakes\PycharmProjects\book_project\app\__init__.py:69]
2025-04-18 14:07:51,395 ERROR: Exception on /books/books [GET] [in C:\Users\rakes\PycharmProjects\book_project\.venv\Lib\site-packages\flask\app.py:875]
Traceback (most recent call last):
  File "C:\Users\rakes\PycharmProjects\book_project\.venv\Lib\site-packages\flask\app.py", line 1511, in wsgi_app
    response = self.full_dispatch_request()
               ^^^^^^^^^^^^^^^^^^^^^^^^^^^^
  File "C:\Users\rakes\PycharmProjects\book_project\.venv\Lib\site-packages\flask\app.py", line 919, in full_dispatch_request
    rv = self.handle_user_exception(e)
         ^^^^^^^^^^^^^^^^^^^^^^^^^^^^^
  File "C:\Users\rakes\PycharmProjects\book_project\.venv\Lib\site-packages\flask\app.py", line 917, in full_dispatch_request
    rv = self.dispatch_request()
         ^^^^^^^^^^^^^^^^^^^^^^^
  File "C:\Users\rakes\PycharmProjects\book_project\.venv\Lib\site-packages\flask\app.py", line 902, in dispatch_request
    return self.ensure_sync(self.view_functions[rule.endpoint])(**view_args)  # type: ignore[no-any-return]
           ^^^^^^^^^^^^^^^^^^^^^^^^^^^^^^^^^^^^^^^^^^^^^^^^^^^^^^^^^^^^^^^^^
  File "C:\Users\rakes\PycharmProjects\book_project\app\routes\book_routes.py", line 29, in book_list
    books = Book.query.filter(*filter_query).paginate(page, per_page, False)
            ^^^^^^^^^^^^^^^^^^^^^^^^^^^^^^^^^^^^^^^^^^^^^^^^^^^^^^^^^^^^^^^^
TypeError: Query.paginate() takes 1 positional argument but 4 were given
2025-04-18 14:07:53,666 ERROR: Exception on /books/books [GET] [in C:\Users\rakes\PycharmProjects\book_project\.venv\Lib\site-packages\flask\app.py:875]
Traceback (most recent call last):
  File "C:\Users\rakes\PycharmProjects\book_project\.venv\Lib\site-packages\flask\app.py", line 1511, in wsgi_app
    response = self.full_dispatch_request()
               ^^^^^^^^^^^^^^^^^^^^^^^^^^^^
  File "C:\Users\rakes\PycharmProjects\book_project\.venv\Lib\site-packages\flask\app.py", line 919, in full_dispatch_request
    rv = self.handle_user_exception(e)
         ^^^^^^^^^^^^^^^^^^^^^^^^^^^^^
  File "C:\Users\rakes\PycharmProjects\book_project\.venv\Lib\site-packages\flask\app.py", line 917, in full_dispatch_request
    rv = self.dispatch_request()
         ^^^^^^^^^^^^^^^^^^^^^^^
  File "C:\Users\rakes\PycharmProjects\book_project\.venv\Lib\site-packages\flask\app.py", line 902, in dispatch_request
    return self.ensure_sync(self.view_functions[rule.endpoint])(**view_args)  # type: ignore[no-any-return]
           ^^^^^^^^^^^^^^^^^^^^^^^^^^^^^^^^^^^^^^^^^^^^^^^^^^^^^^^^^^^^^^^^^
  File "C:\Users\rakes\PycharmProjects\book_project\app\routes\book_routes.py", line 29, in book_list
    books = Book.query.filter(*filter_query).paginate(page, per_page, False)
            ^^^^^^^^^^^^^^^^^^^^^^^^^^^^^^^^^^^^^^^^^^^^^^^^^^^^^^^^^^^^^^^^
TypeError: Query.paginate() takes 1 positional argument but 4 were given
2025-04-18 14:07:55,384 ERROR: Exception on /books/books [GET] [in C:\Users\rakes\PycharmProjects\book_project\.venv\Lib\site-packages\flask\app.py:875]
Traceback (most recent call last):
  File "C:\Users\rakes\PycharmProjects\book_project\.venv\Lib\site-packages\flask\app.py", line 1511, in wsgi_app
    response = self.full_dispatch_request()
               ^^^^^^^^^^^^^^^^^^^^^^^^^^^^
  File "C:\Users\rakes\PycharmProjects\book_project\.venv\Lib\site-packages\flask\app.py", line 919, in full_dispatch_request
    rv = self.handle_user_exception(e)
         ^^^^^^^^^^^^^^^^^^^^^^^^^^^^^
  File "C:\Users\rakes\PycharmProjects\book_project\.venv\Lib\site-packages\flask\app.py", line 917, in full_dispatch_request
    rv = self.dispatch_request()
         ^^^^^^^^^^^^^^^^^^^^^^^
  File "C:\Users\rakes\PycharmProjects\book_project\.venv\Lib\site-packages\flask\app.py", line 902, in dispatch_request
    return self.ensure_sync(self.view_functions[rule.endpoint])(**view_args)  # type: ignore[no-any-return]
           ^^^^^^^^^^^^^^^^^^^^^^^^^^^^^^^^^^^^^^^^^^^^^^^^^^^^^^^^^^^^^^^^^
  File "C:\Users\rakes\PycharmProjects\book_project\app\routes\book_routes.py", line 29, in book_list
    books = Book.query.filter(*filter_query).paginate(page, per_page, False)
            ^^^^^^^^^^^^^^^^^^^^^^^^^^^^^^^^^^^^^^^^^^^^^^^^^^^^^^^^^^^^^^^^
TypeError: Query.paginate() takes 1 positional argument but 4 were given
2025-04-18 14:07:55,810 ERROR: Exception on /books/books [GET] [in C:\Users\rakes\PycharmProjects\book_project\.venv\Lib\site-packages\flask\app.py:875]
Traceback (most recent call last):
  File "C:\Users\rakes\PycharmProjects\book_project\.venv\Lib\site-packages\flask\app.py", line 1511, in wsgi_app
    response = self.full_dispatch_request()
               ^^^^^^^^^^^^^^^^^^^^^^^^^^^^
  File "C:\Users\rakes\PycharmProjects\book_project\.venv\Lib\site-packages\flask\app.py", line 919, in full_dispatch_request
    rv = self.handle_user_exception(e)
         ^^^^^^^^^^^^^^^^^^^^^^^^^^^^^
  File "C:\Users\rakes\PycharmProjects\book_project\.venv\Lib\site-packages\flask\app.py", line 917, in full_dispatch_request
    rv = self.dispatch_request()
         ^^^^^^^^^^^^^^^^^^^^^^^
  File "C:\Users\rakes\PycharmProjects\book_project\.venv\Lib\site-packages\flask\app.py", line 902, in dispatch_request
    return self.ensure_sync(self.view_functions[rule.endpoint])(**view_args)  # type: ignore[no-any-return]
           ^^^^^^^^^^^^^^^^^^^^^^^^^^^^^^^^^^^^^^^^^^^^^^^^^^^^^^^^^^^^^^^^^
  File "C:\Users\rakes\PycharmProjects\book_project\app\routes\book_routes.py", line 29, in book_list
    books = Book.query.filter(*filter_query).paginate(page, per_page, False)
            ^^^^^^^^^^^^^^^^^^^^^^^^^^^^^^^^^^^^^^^^^^^^^^^^^^^^^^^^^^^^^^^^
TypeError: Query.paginate() takes 1 positional argument but 4 were given
2025-04-18 14:07:55,919 ERROR: Exception on /books/books [GET] [in C:\Users\rakes\PycharmProjects\book_project\.venv\Lib\site-packages\flask\app.py:875]
Traceback (most recent call last):
  File "C:\Users\rakes\PycharmProjects\book_project\.venv\Lib\site-packages\flask\app.py", line 1511, in wsgi_app
    response = self.full_dispatch_request()
               ^^^^^^^^^^^^^^^^^^^^^^^^^^^^
  File "C:\Users\rakes\PycharmProjects\book_project\.venv\Lib\site-packages\flask\app.py", line 919, in full_dispatch_request
    rv = self.handle_user_exception(e)
         ^^^^^^^^^^^^^^^^^^^^^^^^^^^^^
  File "C:\Users\rakes\PycharmProjects\book_project\.venv\Lib\site-packages\flask\app.py", line 917, in full_dispatch_request
    rv = self.dispatch_request()
         ^^^^^^^^^^^^^^^^^^^^^^^
  File "C:\Users\rakes\PycharmProjects\book_project\.venv\Lib\site-packages\flask\app.py", line 902, in dispatch_request
    return self.ensure_sync(self.view_functions[rule.endpoint])(**view_args)  # type: ignore[no-any-return]
           ^^^^^^^^^^^^^^^^^^^^^^^^^^^^^^^^^^^^^^^^^^^^^^^^^^^^^^^^^^^^^^^^^
  File "C:\Users\rakes\PycharmProjects\book_project\app\routes\book_routes.py", line 29, in book_list
    books = Book.query.filter(*filter_query).paginate(page, per_page, False)
            ^^^^^^^^^^^^^^^^^^^^^^^^^^^^^^^^^^^^^^^^^^^^^^^^^^^^^^^^^^^^^^^^
TypeError: Query.paginate() takes 1 positional argument but 4 were given
2025-04-18 14:08:12,917 INFO: BookApp startup [in C:\Users\rakes\PycharmProjects\book_project\app\__init__.py:69]
2025-04-18 14:08:26,342 ERROR: Exception on /books/books [GET] [in C:\Users\rakes\PycharmProjects\book_project\.venv\Lib\site-packages\flask\app.py:875]
Traceback (most recent call last):
  File "C:\Users\rakes\PycharmProjects\book_project\.venv\Lib\site-packages\flask\app.py", line 1511, in wsgi_app
    response = self.full_dispatch_request()
               ^^^^^^^^^^^^^^^^^^^^^^^^^^^^
  File "C:\Users\rakes\PycharmProjects\book_project\.venv\Lib\site-packages\flask\app.py", line 919, in full_dispatch_request
    rv = self.handle_user_exception(e)
         ^^^^^^^^^^^^^^^^^^^^^^^^^^^^^
  File "C:\Users\rakes\PycharmProjects\book_project\.venv\Lib\site-packages\flask\app.py", line 917, in full_dispatch_request
    rv = self.dispatch_request()
         ^^^^^^^^^^^^^^^^^^^^^^^
  File "C:\Users\rakes\PycharmProjects\book_project\.venv\Lib\site-packages\flask\app.py", line 902, in dispatch_request
    return self.ensure_sync(self.view_functions[rule.endpoint])(**view_args)  # type: ignore[no-any-return]
           ^^^^^^^^^^^^^^^^^^^^^^^^^^^^^^^^^^^^^^^^^^^^^^^^^^^^^^^^^^^^^^^^^
  File "C:\Users\rakes\PycharmProjects\book_project\app\routes\book_routes.py", line 29, in book_list
    books = Book.query.filter(*filter_query).paginate(page, per_page, False)
            ^^^^^^^^^^^^^^^^^^^^^^^^^^^^^^^^^^^^^^^^^^^^^^^^^^^^^^^^^^^^^^^^
TypeError: Query.paginate() takes 1 positional argument but 4 were given
2025-04-18 14:11:18,130 INFO: BookApp startup [in C:\Users\rakes\PycharmProjects\book_project\app\__init__.py:69]
2025-04-18 14:11:33,753 ERROR: Exception on /books/books [GET] [in C:\Users\rakes\PycharmProjects\book_project\.venv\Lib\site-packages\flask\app.py:875]
Traceback (most recent call last):
  File "C:\Users\rakes\PycharmProjects\book_project\.venv\Lib\site-packages\flask\app.py", line 1511, in wsgi_app
    response = self.full_dispatch_request()
               ^^^^^^^^^^^^^^^^^^^^^^^^^^^^
  File "C:\Users\rakes\PycharmProjects\book_project\.venv\Lib\site-packages\flask\app.py", line 919, in full_dispatch_request
    rv = self.handle_user_exception(e)
         ^^^^^^^^^^^^^^^^^^^^^^^^^^^^^
  File "C:\Users\rakes\PycharmProjects\book_project\.venv\Lib\site-packages\flask\app.py", line 917, in full_dispatch_request
    rv = self.dispatch_request()
         ^^^^^^^^^^^^^^^^^^^^^^^
  File "C:\Users\rakes\PycharmProjects\book_project\.venv\Lib\site-packages\flask\app.py", line 902, in dispatch_request
    return self.ensure_sync(self.view_functions[rule.endpoint])(**view_args)  # type: ignore[no-any-return]
           ^^^^^^^^^^^^^^^^^^^^^^^^^^^^^^^^^^^^^^^^^^^^^^^^^^^^^^^^^^^^^^^^^
  File "C:\Users\rakes\PycharmProjects\book_project\app\routes\book_routes.py", line 31, in book_list
    return render_template('book_list.html', books=books.items, page=page, total_pages=total_pages, search=search)
           ^^^^^^^^^^^^^^^^^^^^^^^^^^^^^^^^^^^^^^^^^^^^^^^^^^^^^^^^^^^^^^^^^^^^^^^^^^^^^^^^^^^^^^^^^^^^^^^^^^^^^^^
  File "C:\Users\rakes\PycharmProjects\book_project\.venv\Lib\site-packages\flask\templating.py", line 150, in render_template
    return _render(app, template, context)
           ^^^^^^^^^^^^^^^^^^^^^^^^^^^^^^^
  File "C:\Users\rakes\PycharmProjects\book_project\.venv\Lib\site-packages\flask\templating.py", line 131, in _render
    rv = template.render(context)
         ^^^^^^^^^^^^^^^^^^^^^^^^
  File "C:\Users\rakes\PycharmProjects\book_project\.venv\Lib\site-packages\jinja2\environment.py", line 1295, in render
    self.environment.handle_exception()
  File "C:\Users\rakes\PycharmProjects\book_project\.venv\Lib\site-packages\jinja2\environment.py", line 942, in handle_exception
    raise rewrite_traceback_stack(source=source)
  File "C:\Users\rakes\PycharmProjects\book_project\app\templates\book_list.html", line 1, in top-level template code
    {% extends 'base.html' %}
  File "C:\Users\rakes\PycharmProjects\book_project\app\templates\base.html", line 19, in top-level template code
    <a class="nav-link" href="{{ url_for('auth.logout') }}">Logout</a>
    ^^^^^^^^^^^^^^^^^^^^^^^^^
  File "C:\Users\rakes\PycharmProjects\book_project\.venv\Lib\site-packages\flask\app.py", line 1121, in url_for
    return self.handle_url_build_error(error, endpoint, values)
           ^^^^^^^^^^^^^^^^^^^^^^^^^^^^^^^^^^^^^^^^^^^^^^^^^^^^
  File "C:\Users\rakes\PycharmProjects\book_project\.venv\Lib\site-packages\flask\app.py", line 1110, in url_for
    rv = url_adapter.build(  # type: ignore[union-attr]
         ^^^^^^^^^^^^^^^^^^^^^^^^^^^^^^^^^^^^^^^^^^^^^^
  File "C:\Users\rakes\PycharmProjects\book_project\.venv\Lib\site-packages\werkzeug\routing\map.py", line 924, in build
    raise BuildError(endpoint, values, method, self)
werkzeug.routing.exceptions.BuildError: Could not build url for endpoint 'auth.logout'. Did you mean 'auth_bp.logout' instead?
2025-04-18 14:15:35,290 INFO: BookApp startup [in C:\Users\rakes\PycharmProjects\book_project\app\__init__.py:69]
2025-04-18 14:16:08,129 ERROR: Exception on /auth/login [POST] [in C:\Users\rakes\PycharmProjects\book_project\.venv\Lib\site-packages\flask\app.py:875]
Traceback (most recent call last):
  File "C:\Users\rakes\PycharmProjects\book_project\.venv\Lib\site-packages\flask\app.py", line 1511, in wsgi_app
    response = self.full_dispatch_request()
               ^^^^^^^^^^^^^^^^^^^^^^^^^^^^
  File "C:\Users\rakes\PycharmProjects\book_project\.venv\Lib\site-packages\flask\app.py", line 919, in full_dispatch_request
    rv = self.handle_user_exception(e)
         ^^^^^^^^^^^^^^^^^^^^^^^^^^^^^
  File "C:\Users\rakes\PycharmProjects\book_project\.venv\Lib\site-packages\flask\app.py", line 917, in full_dispatch_request
    rv = self.dispatch_request()
         ^^^^^^^^^^^^^^^^^^^^^^^
  File "C:\Users\rakes\PycharmProjects\book_project\.venv\Lib\site-packages\flask\app.py", line 902, in dispatch_request
    return self.ensure_sync(self.view_functions[rule.endpoint])(**view_args)  # type: ignore[no-any-return]
           ^^^^^^^^^^^^^^^^^^^^^^^^^^^^^^^^^^^^^^^^^^^^^^^^^^^^^^^^^^^^^^^^^
  File "C:\Users\rakes\PycharmProjects\book_project\app\routes\auth_routes.py", line 19, in login
    return redirect(next_page or url_for('book_bp.index'))
                                 ^^^^^^^^^^^^^^^^^^^^^^^^
  File "C:\Users\rakes\PycharmProjects\book_project\.venv\Lib\site-packages\flask\helpers.py", line 232, in url_for
    return current_app.url_for(
           ^^^^^^^^^^^^^^^^^^^^
  File "C:\Users\rakes\PycharmProjects\book_project\.venv\Lib\site-packages\flask\app.py", line 1121, in url_for
    return self.handle_url_build_error(error, endpoint, values)
           ^^^^^^^^^^^^^^^^^^^^^^^^^^^^^^^^^^^^^^^^^^^^^^^^^^^^
  File "C:\Users\rakes\PycharmProjects\book_project\.venv\Lib\site-packages\flask\app.py", line 1110, in url_for
    rv = url_adapter.build(  # type: ignore[union-attr]
         ^^^^^^^^^^^^^^^^^^^^^^^^^^^^^^^^^^^^^^^^^^^^^^
  File "C:\Users\rakes\PycharmProjects\book_project\.venv\Lib\site-packages\werkzeug\routing\map.py", line 924, in build
    raise BuildError(endpoint, values, method, self)
werkzeug.routing.exceptions.BuildError: Could not build url for endpoint 'book_bp.index'. Did you mean 'book_bp.delete' instead?
2025-04-18 14:21:35,702 INFO: BookApp startup [in C:\Users\rakes\PycharmProjects\book_project\app\__init__.py:69]
2025-04-18 14:22:09,307 ERROR: Exception on /books/books [GET] [in C:\Users\rakes\PycharmProjects\book_project\.venv\Lib\site-packages\flask\app.py:875]
Traceback (most recent call last):
  File "C:\Users\rakes\PycharmProjects\book_project\.venv\Lib\site-packages\flask\app.py", line 1511, in wsgi_app
    response = self.full_dispatch_request()
               ^^^^^^^^^^^^^^^^^^^^^^^^^^^^
  File "C:\Users\rakes\PycharmProjects\book_project\.venv\Lib\site-packages\flask\app.py", line 919, in full_dispatch_request
    rv = self.handle_user_exception(e)
         ^^^^^^^^^^^^^^^^^^^^^^^^^^^^^
  File "C:\Users\rakes\PycharmProjects\book_project\.venv\Lib\site-packages\flask\app.py", line 917, in full_dispatch_request
    rv = self.dispatch_request()
         ^^^^^^^^^^^^^^^^^^^^^^^
  File "C:\Users\rakes\PycharmProjects\book_project\.venv\Lib\site-packages\flask\app.py", line 902, in dispatch_request
    return self.ensure_sync(self.view_functions[rule.endpoint])(**view_args)  # type: ignore[no-any-return]
           ^^^^^^^^^^^^^^^^^^^^^^^^^^^^^^^^^^^^^^^^^^^^^^^^^^^^^^^^^^^^^^^^^
  File "C:\Users\rakes\PycharmProjects\book_project\app\routes\book_routes.py", line 23, in book_list
    Book.genre.ilike(f'%{search}%')
    ^^^^^^^^^^
AttributeError: type object 'Book' has no attribute 'genre'
2025-04-18 14:24:17,036 INFO: BookApp startup [in C:\Users\rakes\PycharmProjects\book_project\app\__init__.py:69]
2025-04-18 14:24:28,112 INFO: BookApp startup [in C:\Users\rakes\PycharmProjects\book_project\app\__init__.py:69]
2025-04-18 14:24:45,723 INFO: BookApp startup [in C:\Users\rakes\PycharmProjects\book_project\app\__init__.py:69]
2025-04-18 14:27:35,329 INFO: BookApp startup [in C:\Users\rakes\PycharmProjects\book_project\app\__init__.py:69]
2025-04-18 14:40:04,056 INFO: BookApp startup [in C:\Users\rakes\PycharmProjects\book_project\app\__init__.py:69]
2025-04-18 14:41:41,798 INFO: BookApp startup [in C:\Users\rakes\PycharmProjects\book_project\app\__init__.py:69]
2025-04-18 22:12:34,894 INFO: BookApp startup [in C:\Users\rakes\PycharmProjects\book_project\app\__init__.py:69]
2025-04-18 22:17:27,461 INFO: BookApp startup [in C:\Users\rakes\PycharmProjects\book_project\app\__init__.py:69]
2025-04-18 22:21:33,543 INFO: BookApp startup [in C:\Users\rakes\PycharmProjects\book_project\app\__init__.py:69]
2025-04-18 22:24:11,510 INFO: BookApp startup [in C:\Users\rakes\PycharmProjects\book_project\app\__init__.py:65]
2025-04-18 22:28:47,404 INFO: BookApp startup [in C:\Users\rakes\PycharmProjects\book_project\app\__init__.py:65]
2025-04-18 22:38:22,117 INFO: BookApp startup [in C:\Users\rakes\PycharmProjects\book_project\app\__init__.py:65]
2025-04-18 22:57:29,520 INFO: BookApp startup [in C:\Users\rakes\PycharmProjects\book_project\app\__init__.py:65]
2025-04-18 23:00:41,693 INFO: BookApp startup [in C:\Users\rakes\PycharmProjects\book_project\app\__init__.py:65]
2025-04-18 23:00:49,353 ERROR: Exception on /auth/login [GET] [in C:\Users\rakes\PycharmProjects\book_project\.venv\Lib\site-packages\flask\app.py:875]
Traceback (most recent call last):
  File "C:\Users\rakes\PycharmProjects\book_project\.venv\Lib\site-packages\flask\app.py", line 1511, in wsgi_app
    response = self.full_dispatch_request()
               ^^^^^^^^^^^^^^^^^^^^^^^^^^^^
  File "C:\Users\rakes\PycharmProjects\book_project\.venv\Lib\site-packages\flask\app.py", line 919, in full_dispatch_request
    rv = self.handle_user_exception(e)
         ^^^^^^^^^^^^^^^^^^^^^^^^^^^^^
  File "C:\Users\rakes\PycharmProjects\book_project\.venv\Lib\site-packages\flask\app.py", line 917, in full_dispatch_request
    rv = self.dispatch_request()
         ^^^^^^^^^^^^^^^^^^^^^^^
  File "C:\Users\rakes\PycharmProjects\book_project\.venv\Lib\site-packages\flask\app.py", line 902, in dispatch_request
    return self.ensure_sync(self.view_functions[rule.endpoint])(**view_args)  # type: ignore[no-any-return]
           ^^^^^^^^^^^^^^^^^^^^^^^^^^^^^^^^^^^^^^^^^^^^^^^^^^^^^^^^^^^^^^^^^
  File "C:\Users\rakes\PycharmProjects\book_project\app\routes\auth_routes.py", line 25, in login
    return render_template('login.html')
           ^^^^^^^^^^^^^^^^^^^^^^^^^^^^^
  File "C:\Users\rakes\PycharmProjects\book_project\.venv\Lib\site-packages\flask\templating.py", line 150, in render_template
    return _render(app, template, context)
           ^^^^^^^^^^^^^^^^^^^^^^^^^^^^^^^
  File "C:\Users\rakes\PycharmProjects\book_project\.venv\Lib\site-packages\flask\templating.py", line 131, in _render
    rv = template.render(context)
         ^^^^^^^^^^^^^^^^^^^^^^^^
  File "C:\Users\rakes\PycharmProjects\book_project\.venv\Lib\site-packages\jinja2\environment.py", line 1295, in render
    self.environment.handle_exception()
  File "C:\Users\rakes\PycharmProjects\book_project\.venv\Lib\site-packages\jinja2\environment.py", line 942, in handle_exception
    raise rewrite_traceback_stack(source=source)
  File "C:\Users\rakes\PycharmProjects\book_project\app\templates\login.html", line 59, in top-level template code
    <p>Don't have an account? <a href="{{ url_for('book_bp.register') }}" class="btn btn-success">Sign up</a></p>
    ^^^^^^^^^^^^^^^^^^^^^^^^^
  File "C:\Users\rakes\PycharmProjects\book_project\.venv\Lib\site-packages\flask\app.py", line 1121, in url_for
    return self.handle_url_build_error(error, endpoint, values)
           ^^^^^^^^^^^^^^^^^^^^^^^^^^^^^^^^^^^^^^^^^^^^^^^^^^^^
  File "C:\Users\rakes\PycharmProjects\book_project\.venv\Lib\site-packages\flask\app.py", line 1110, in url_for
    rv = url_adapter.build(  # type: ignore[union-attr]
         ^^^^^^^^^^^^^^^^^^^^^^^^^^^^^^^^^^^^^^^^^^^^^^
  File "C:\Users\rakes\PycharmProjects\book_project\.venv\Lib\site-packages\werkzeug\routing\map.py", line 924, in build
    raise BuildError(endpoint, values, method, self)
werkzeug.routing.exceptions.BuildError: Could not build url for endpoint 'book_bp.register'. Did you mean 'book_bp.edit' instead?
2025-04-18 23:02:05,451 ERROR: Exception on /auth/login [GET] [in C:\Users\rakes\PycharmProjects\book_project\.venv\Lib\site-packages\flask\app.py:875]
Traceback (most recent call last):
  File "C:\Users\rakes\PycharmProjects\book_project\.venv\Lib\site-packages\flask\app.py", line 1511, in wsgi_app
    response = self.full_dispatch_request()
               ^^^^^^^^^^^^^^^^^^^^^^^^^^^^
  File "C:\Users\rakes\PycharmProjects\book_project\.venv\Lib\site-packages\flask\app.py", line 919, in full_dispatch_request
    rv = self.handle_user_exception(e)
         ^^^^^^^^^^^^^^^^^^^^^^^^^^^^^
  File "C:\Users\rakes\PycharmProjects\book_project\.venv\Lib\site-packages\flask\app.py", line 917, in full_dispatch_request
    rv = self.dispatch_request()
         ^^^^^^^^^^^^^^^^^^^^^^^
  File "C:\Users\rakes\PycharmProjects\book_project\.venv\Lib\site-packages\flask\app.py", line 902, in dispatch_request
    return self.ensure_sync(self.view_functions[rule.endpoint])(**view_args)  # type: ignore[no-any-return]
           ^^^^^^^^^^^^^^^^^^^^^^^^^^^^^^^^^^^^^^^^^^^^^^^^^^^^^^^^^^^^^^^^^
  File "C:\Users\rakes\PycharmProjects\book_project\app\routes\auth_routes.py", line 25, in login
    return render_template('login.html')
           ^^^^^^^^^^^^^^^^^^^^^^^^^^^^^
  File "C:\Users\rakes\PycharmProjects\book_project\.venv\Lib\site-packages\flask\templating.py", line 150, in render_template
    return _render(app, template, context)
           ^^^^^^^^^^^^^^^^^^^^^^^^^^^^^^^
  File "C:\Users\rakes\PycharmProjects\book_project\.venv\Lib\site-packages\flask\templating.py", line 131, in _render
    rv = template.render(context)
         ^^^^^^^^^^^^^^^^^^^^^^^^
  File "C:\Users\rakes\PycharmProjects\book_project\.venv\Lib\site-packages\jinja2\environment.py", line 1295, in render
    self.environment.handle_exception()
  File "C:\Users\rakes\PycharmProjects\book_project\.venv\Lib\site-packages\jinja2\environment.py", line 942, in handle_exception
    raise rewrite_traceback_stack(source=source)
  File "C:\Users\rakes\PycharmProjects\book_project\app\templates\login.html", line 59, in top-level template code
    <p>Don't have an account? <a href="{{ url_for('book_bp.register') }}" class="btn btn-success">Sign up</a></p>
    ^^^^^^^^^^^^^^^^^^^^^^^^^
  File "C:\Users\rakes\PycharmProjects\book_project\.venv\Lib\site-packages\flask\app.py", line 1121, in url_for
    return self.handle_url_build_error(error, endpoint, values)
           ^^^^^^^^^^^^^^^^^^^^^^^^^^^^^^^^^^^^^^^^^^^^^^^^^^^^
  File "C:\Users\rakes\PycharmProjects\book_project\.venv\Lib\site-packages\flask\app.py", line 1110, in url_for
    rv = url_adapter.build(  # type: ignore[union-attr]
         ^^^^^^^^^^^^^^^^^^^^^^^^^^^^^^^^^^^^^^^^^^^^^^
  File "C:\Users\rakes\PycharmProjects\book_project\.venv\Lib\site-packages\werkzeug\routing\map.py", line 924, in build
    raise BuildError(endpoint, values, method, self)
werkzeug.routing.exceptions.BuildError: Could not build url for endpoint 'book_bp.register'. Did you mean 'book_bp.edit' instead?
2025-04-18 23:02:30,825 INFO: BookApp startup [in C:\Users\rakes\PycharmProjects\book_project\app\__init__.py:65]
2025-04-18 23:02:40,881 ERROR: Exception on /auth/login [GET] [in C:\Users\rakes\PycharmProjects\book_project\.venv\Lib\site-packages\flask\app.py:875]
Traceback (most recent call last):
  File "C:\Users\rakes\PycharmProjects\book_project\.venv\Lib\site-packages\flask\app.py", line 1511, in wsgi_app
    response = self.full_dispatch_request()
               ^^^^^^^^^^^^^^^^^^^^^^^^^^^^
  File "C:\Users\rakes\PycharmProjects\book_project\.venv\Lib\site-packages\flask\app.py", line 919, in full_dispatch_request
    rv = self.handle_user_exception(e)
         ^^^^^^^^^^^^^^^^^^^^^^^^^^^^^
  File "C:\Users\rakes\PycharmProjects\book_project\.venv\Lib\site-packages\flask\app.py", line 917, in full_dispatch_request
    rv = self.dispatch_request()
         ^^^^^^^^^^^^^^^^^^^^^^^
  File "C:\Users\rakes\PycharmProjects\book_project\.venv\Lib\site-packages\flask\app.py", line 902, in dispatch_request
    return self.ensure_sync(self.view_functions[rule.endpoint])(**view_args)  # type: ignore[no-any-return]
           ^^^^^^^^^^^^^^^^^^^^^^^^^^^^^^^^^^^^^^^^^^^^^^^^^^^^^^^^^^^^^^^^^
  File "C:\Users\rakes\PycharmProjects\book_project\app\routes\auth_routes.py", line 25, in login
    return render_template('login.html')
           ^^^^^^^^^^^^^^^^^^^^^^^^^^^^^
  File "C:\Users\rakes\PycharmProjects\book_project\.venv\Lib\site-packages\flask\templating.py", line 150, in render_template
    return _render(app, template, context)
           ^^^^^^^^^^^^^^^^^^^^^^^^^^^^^^^
  File "C:\Users\rakes\PycharmProjects\book_project\.venv\Lib\site-packages\flask\templating.py", line 131, in _render
    rv = template.render(context)
         ^^^^^^^^^^^^^^^^^^^^^^^^
  File "C:\Users\rakes\PycharmProjects\book_project\.venv\Lib\site-packages\jinja2\environment.py", line 1295, in render
    self.environment.handle_exception()
  File "C:\Users\rakes\PycharmProjects\book_project\.venv\Lib\site-packages\jinja2\environment.py", line 942, in handle_exception
    raise rewrite_traceback_stack(source=source)
  File "C:\Users\rakes\PycharmProjects\book_project\app\templates\login.html", line 59, in top-level template code
    <p>Don't have an account? <a href="{{ url_for('book_bp.register') }}" class="btn btn-success">Sign up</a></p>
    ^^^^^^^^^^^^^^^^^^^^^^^^^
  File "C:\Users\rakes\PycharmProjects\book_project\.venv\Lib\site-packages\flask\app.py", line 1121, in url_for
    return self.handle_url_build_error(error, endpoint, values)
           ^^^^^^^^^^^^^^^^^^^^^^^^^^^^^^^^^^^^^^^^^^^^^^^^^^^^
  File "C:\Users\rakes\PycharmProjects\book_project\.venv\Lib\site-packages\flask\app.py", line 1110, in url_for
    rv = url_adapter.build(  # type: ignore[union-attr]
         ^^^^^^^^^^^^^^^^^^^^^^^^^^^^^^^^^^^^^^^^^^^^^^
  File "C:\Users\rakes\PycharmProjects\book_project\.venv\Lib\site-packages\werkzeug\routing\map.py", line 924, in build
    raise BuildError(endpoint, values, method, self)
werkzeug.routing.exceptions.BuildError: Could not build url for endpoint 'book_bp.register'. Did you mean 'book_bp.edit' instead?
2025-04-18 23:03:55,610 INFO: BookApp startup [in C:\Users\rakes\PycharmProjects\book_project\app\__init__.py:65]
2025-04-18 23:04:00,097 ERROR: Exception on /auth/login [GET] [in C:\Users\rakes\PycharmProjects\book_project\.venv\Lib\site-packages\flask\app.py:875]
Traceback (most recent call last):
  File "C:\Users\rakes\PycharmProjects\book_project\.venv\Lib\site-packages\flask\app.py", line 1511, in wsgi_app
    response = self.full_dispatch_request()
               ^^^^^^^^^^^^^^^^^^^^^^^^^^^^
  File "C:\Users\rakes\PycharmProjects\book_project\.venv\Lib\site-packages\flask\app.py", line 919, in full_dispatch_request
    rv = self.handle_user_exception(e)
         ^^^^^^^^^^^^^^^^^^^^^^^^^^^^^
  File "C:\Users\rakes\PycharmProjects\book_project\.venv\Lib\site-packages\flask\app.py", line 917, in full_dispatch_request
    rv = self.dispatch_request()
         ^^^^^^^^^^^^^^^^^^^^^^^
  File "C:\Users\rakes\PycharmProjects\book_project\.venv\Lib\site-packages\flask\app.py", line 902, in dispatch_request
    return self.ensure_sync(self.view_functions[rule.endpoint])(**view_args)  # type: ignore[no-any-return]
           ^^^^^^^^^^^^^^^^^^^^^^^^^^^^^^^^^^^^^^^^^^^^^^^^^^^^^^^^^^^^^^^^^
  File "C:\Users\rakes\PycharmProjects\book_project\app\routes\auth_routes.py", line 25, in login
    return render_template('login.html')
           ^^^^^^^^^^^^^^^^^^^^^^^^^^^^^
  File "C:\Users\rakes\PycharmProjects\book_project\.venv\Lib\site-packages\flask\templating.py", line 150, in render_template
    return _render(app, template, context)
           ^^^^^^^^^^^^^^^^^^^^^^^^^^^^^^^
  File "C:\Users\rakes\PycharmProjects\book_project\.venv\Lib\site-packages\flask\templating.py", line 131, in _render
    rv = template.render(context)
         ^^^^^^^^^^^^^^^^^^^^^^^^
  File "C:\Users\rakes\PycharmProjects\book_project\.venv\Lib\site-packages\jinja2\environment.py", line 1295, in render
    self.environment.handle_exception()
  File "C:\Users\rakes\PycharmProjects\book_project\.venv\Lib\site-packages\jinja2\environment.py", line 942, in handle_exception
    raise rewrite_traceback_stack(source=source)
  File "C:\Users\rakes\PycharmProjects\book_project\app\templates\login.html", line 59, in top-level template code
    <p>Don't have an account? <a href="{{ url_for('register.html') }}" class="btn btn-success">Sign up</a></p>
    ^^^^^^^^^^^^^^^^^^^^^^^^^
  File "C:\Users\rakes\PycharmProjects\book_project\.venv\Lib\site-packages\flask\app.py", line 1121, in url_for
    return self.handle_url_build_error(error, endpoint, values)
           ^^^^^^^^^^^^^^^^^^^^^^^^^^^^^^^^^^^^^^^^^^^^^^^^^^^^
  File "C:\Users\rakes\PycharmProjects\book_project\.venv\Lib\site-packages\flask\app.py", line 1110, in url_for
    rv = url_adapter.build(  # type: ignore[union-attr]
         ^^^^^^^^^^^^^^^^^^^^^^^^^^^^^^^^^^^^^^^^^^^^^^
  File "C:\Users\rakes\PycharmProjects\book_project\.venv\Lib\site-packages\werkzeug\routing\map.py", line 924, in build
    raise BuildError(endpoint, values, method, self)
werkzeug.routing.exceptions.BuildError: Could not build url for endpoint 'register.html'. Did you mean 'auth_bp.register' instead?
2025-04-18 23:04:51,303 INFO: BookApp startup [in C:\Users\rakes\PycharmProjects\book_project\app\__init__.py:65]
2025-04-19 10:00:31,290 INFO: BookApp startup [in C:\Users\rakes\PycharmProjects\book_project\app\__init__.py:65]
2025-04-19 10:02:01,723 ERROR: Exception on /books/books [GET] [in C:\Users\rakes\PycharmProjects\book_project\.venv\Lib\site-packages\flask\app.py:875]
Traceback (most recent call last):
  File "C:\Users\rakes\PycharmProjects\book_project\.venv\Lib\site-packages\flask\app.py", line 1511, in wsgi_app
    response = self.full_dispatch_request()
               ^^^^^^^^^^^^^^^^^^^^^^^^^^^^
  File "C:\Users\rakes\PycharmProjects\book_project\.venv\Lib\site-packages\flask\app.py", line 919, in full_dispatch_request
    rv = self.handle_user_exception(e)
         ^^^^^^^^^^^^^^^^^^^^^^^^^^^^^
  File "C:\Users\rakes\PycharmProjects\book_project\.venv\Lib\site-packages\flask\app.py", line 917, in full_dispatch_request
    rv = self.dispatch_request()
         ^^^^^^^^^^^^^^^^^^^^^^^
  File "C:\Users\rakes\PycharmProjects\book_project\.venv\Lib\site-packages\flask\app.py", line 902, in dispatch_request
    return self.ensure_sync(self.view_functions[rule.endpoint])(**view_args)  # type: ignore[no-any-return]
           ^^^^^^^^^^^^^^^^^^^^^^^^^^^^^^^^^^^^^^^^^^^^^^^^^^^^^^^^^^^^^^^^^
  File "C:\Users\rakes\PycharmProjects\book_project\app\routes\book_routes.py", line 50, in book_list
    return render_template(
           ^^^^^^^^^^^^^^^^
  File "C:\Users\rakes\PycharmProjects\book_project\.venv\Lib\site-packages\flask\templating.py", line 149, in render_template
    template = app.jinja_env.get_or_select_template(template_name_or_list)
               ^^^^^^^^^^^^^^^^^^^^^^^^^^^^^^^^^^^^^^^^^^^^^^^^^^^^^^^^^^^
  File "C:\Users\rakes\PycharmProjects\book_project\.venv\Lib\site-packages\jinja2\environment.py", line 1087, in get_or_select_template
    return self.get_template(template_name_or_list, parent, globals)
           ^^^^^^^^^^^^^^^^^^^^^^^^^^^^^^^^^^^^^^^^^^^^^^^^^^^^^^^^^
  File "C:\Users\rakes\PycharmProjects\book_project\.venv\Lib\site-packages\jinja2\environment.py", line 1016, in get_template
    return self._load_template(name, globals)
           ^^^^^^^^^^^^^^^^^^^^^^^^^^^^^^^^^^
  File "C:\Users\rakes\PycharmProjects\book_project\.venv\Lib\site-packages\jinja2\environment.py", line 975, in _load_template
    template = self.loader.load(self, name, self.make_globals(globals))
               ^^^^^^^^^^^^^^^^^^^^^^^^^^^^^^^^^^^^^^^^^^^^^^^^^^^^^^^^
  File "C:\Users\rakes\PycharmProjects\book_project\.venv\Lib\site-packages\jinja2\loaders.py", line 138, in load
    code = environment.compile(source, name, filename)
           ^^^^^^^^^^^^^^^^^^^^^^^^^^^^^^^^^^^^^^^^^^^
  File "C:\Users\rakes\PycharmProjects\book_project\.venv\Lib\site-packages\jinja2\environment.py", line 771, in compile
    self.handle_exception(source=source_hint)
  File "C:\Users\rakes\PycharmProjects\book_project\.venv\Lib\site-packages\jinja2\environment.py", line 942, in handle_exception
    raise rewrite_traceback_stack(source=source)
  File "C:\Users\rakes\PycharmProjects\book_project\app\templates\book_list.html", line 62, in template
    {% endif %}
jinja2.exceptions.TemplateSyntaxError: Unexpected end of template. Jinja was looking for the following tags: 'endblock'. The innermost block that needs to be closed is 'block'.
2025-04-19 10:02:03,168 ERROR: Exception on /books/books [GET] [in C:\Users\rakes\PycharmProjects\book_project\.venv\Lib\site-packages\flask\app.py:875]
Traceback (most recent call last):
  File "C:\Users\rakes\PycharmProjects\book_project\.venv\Lib\site-packages\flask\app.py", line 1511, in wsgi_app
    response = self.full_dispatch_request()
               ^^^^^^^^^^^^^^^^^^^^^^^^^^^^
  File "C:\Users\rakes\PycharmProjects\book_project\.venv\Lib\site-packages\flask\app.py", line 919, in full_dispatch_request
    rv = self.handle_user_exception(e)
         ^^^^^^^^^^^^^^^^^^^^^^^^^^^^^
  File "C:\Users\rakes\PycharmProjects\book_project\.venv\Lib\site-packages\flask\app.py", line 917, in full_dispatch_request
    rv = self.dispatch_request()
         ^^^^^^^^^^^^^^^^^^^^^^^
  File "C:\Users\rakes\PycharmProjects\book_project\.venv\Lib\site-packages\flask\app.py", line 902, in dispatch_request
    return self.ensure_sync(self.view_functions[rule.endpoint])(**view_args)  # type: ignore[no-any-return]
           ^^^^^^^^^^^^^^^^^^^^^^^^^^^^^^^^^^^^^^^^^^^^^^^^^^^^^^^^^^^^^^^^^
  File "C:\Users\rakes\PycharmProjects\book_project\app\routes\book_routes.py", line 50, in book_list
    return render_template(
           ^^^^^^^^^^^^^^^^
  File "C:\Users\rakes\PycharmProjects\book_project\.venv\Lib\site-packages\flask\templating.py", line 149, in render_template
    template = app.jinja_env.get_or_select_template(template_name_or_list)
               ^^^^^^^^^^^^^^^^^^^^^^^^^^^^^^^^^^^^^^^^^^^^^^^^^^^^^^^^^^^
  File "C:\Users\rakes\PycharmProjects\book_project\.venv\Lib\site-packages\jinja2\environment.py", line 1087, in get_or_select_template
    return self.get_template(template_name_or_list, parent, globals)
           ^^^^^^^^^^^^^^^^^^^^^^^^^^^^^^^^^^^^^^^^^^^^^^^^^^^^^^^^^
  File "C:\Users\rakes\PycharmProjects\book_project\.venv\Lib\site-packages\jinja2\environment.py", line 1016, in get_template
    return self._load_template(name, globals)
           ^^^^^^^^^^^^^^^^^^^^^^^^^^^^^^^^^^
  File "C:\Users\rakes\PycharmProjects\book_project\.venv\Lib\site-packages\jinja2\environment.py", line 975, in _load_template
    template = self.loader.load(self, name, self.make_globals(globals))
               ^^^^^^^^^^^^^^^^^^^^^^^^^^^^^^^^^^^^^^^^^^^^^^^^^^^^^^^^
  File "C:\Users\rakes\PycharmProjects\book_project\.venv\Lib\site-packages\jinja2\loaders.py", line 138, in load
    code = environment.compile(source, name, filename)
           ^^^^^^^^^^^^^^^^^^^^^^^^^^^^^^^^^^^^^^^^^^^
  File "C:\Users\rakes\PycharmProjects\book_project\.venv\Lib\site-packages\jinja2\environment.py", line 771, in compile
    self.handle_exception(source=source_hint)
  File "C:\Users\rakes\PycharmProjects\book_project\.venv\Lib\site-packages\jinja2\environment.py", line 942, in handle_exception
    raise rewrite_traceback_stack(source=source)
  File "C:\Users\rakes\PycharmProjects\book_project\app\templates\book_list.html", line 62, in template
    {% endif %}
jinja2.exceptions.TemplateSyntaxError: Unexpected end of template. Jinja was looking for the following tags: 'endblock'. The innermost block that needs to be closed is 'block'.
2025-04-19 10:02:11,269 INFO: BookApp startup [in C:\Users\rakes\PycharmProjects\book_project\app\__init__.py:65]
2025-04-19 10:02:40,012 ERROR: Exception on /books/books [GET] [in C:\Users\rakes\PycharmProjects\book_project\.venv\Lib\site-packages\flask\app.py:875]
Traceback (most recent call last):
  File "C:\Users\rakes\PycharmProjects\book_project\.venv\Lib\site-packages\flask\app.py", line 1511, in wsgi_app
    response = self.full_dispatch_request()
               ^^^^^^^^^^^^^^^^^^^^^^^^^^^^
  File "C:\Users\rakes\PycharmProjects\book_project\.venv\Lib\site-packages\flask\app.py", line 919, in full_dispatch_request
    rv = self.handle_user_exception(e)
         ^^^^^^^^^^^^^^^^^^^^^^^^^^^^^
  File "C:\Users\rakes\PycharmProjects\book_project\.venv\Lib\site-packages\flask\app.py", line 917, in full_dispatch_request
    rv = self.dispatch_request()
         ^^^^^^^^^^^^^^^^^^^^^^^
  File "C:\Users\rakes\PycharmProjects\book_project\.venv\Lib\site-packages\flask\app.py", line 902, in dispatch_request
    return self.ensure_sync(self.view_functions[rule.endpoint])(**view_args)  # type: ignore[no-any-return]
           ^^^^^^^^^^^^^^^^^^^^^^^^^^^^^^^^^^^^^^^^^^^^^^^^^^^^^^^^^^^^^^^^^
  File "C:\Users\rakes\PycharmProjects\book_project\app\routes\book_routes.py", line 50, in book_list
    return render_template(
           ^^^^^^^^^^^^^^^^
  File "C:\Users\rakes\PycharmProjects\book_project\.venv\Lib\site-packages\flask\templating.py", line 149, in render_template
    template = app.jinja_env.get_or_select_template(template_name_or_list)
               ^^^^^^^^^^^^^^^^^^^^^^^^^^^^^^^^^^^^^^^^^^^^^^^^^^^^^^^^^^^
  File "C:\Users\rakes\PycharmProjects\book_project\.venv\Lib\site-packages\jinja2\environment.py", line 1087, in get_or_select_template
    return self.get_template(template_name_or_list, parent, globals)
           ^^^^^^^^^^^^^^^^^^^^^^^^^^^^^^^^^^^^^^^^^^^^^^^^^^^^^^^^^
  File "C:\Users\rakes\PycharmProjects\book_project\.venv\Lib\site-packages\jinja2\environment.py", line 1016, in get_template
    return self._load_template(name, globals)
           ^^^^^^^^^^^^^^^^^^^^^^^^^^^^^^^^^^
  File "C:\Users\rakes\PycharmProjects\book_project\.venv\Lib\site-packages\jinja2\environment.py", line 975, in _load_template
    template = self.loader.load(self, name, self.make_globals(globals))
               ^^^^^^^^^^^^^^^^^^^^^^^^^^^^^^^^^^^^^^^^^^^^^^^^^^^^^^^^
  File "C:\Users\rakes\PycharmProjects\book_project\.venv\Lib\site-packages\jinja2\loaders.py", line 138, in load
    code = environment.compile(source, name, filename)
           ^^^^^^^^^^^^^^^^^^^^^^^^^^^^^^^^^^^^^^^^^^^
  File "C:\Users\rakes\PycharmProjects\book_project\.venv\Lib\site-packages\jinja2\environment.py", line 771, in compile
    self.handle_exception(source=source_hint)
  File "C:\Users\rakes\PycharmProjects\book_project\.venv\Lib\site-packages\jinja2\environment.py", line 942, in handle_exception
    raise rewrite_traceback_stack(source=source)
  File "C:\Users\rakes\PycharmProjects\book_project\app\templates\book_list.html", line 62, in template
    {% endif %}
jinja2.exceptions.TemplateSyntaxError: Unexpected end of template. Jinja was looking for the following tags: 'endblock'. The innermost block that needs to be closed is 'block'.
2025-04-19 10:05:34,791 INFO: BookApp startup [in C:\Users\rakes\PycharmProjects\book_project\app\__init__.py:65]
2025-04-19 10:05:54,601 ERROR: Exception on /books/add [GET] [in C:\Users\rakes\PycharmProjects\book_project\.venv\Lib\site-packages\flask\app.py:875]
Traceback (most recent call last):
  File "C:\Users\rakes\PycharmProjects\book_project\.venv\Lib\site-packages\flask\app.py", line 1511, in wsgi_app
    response = self.full_dispatch_request()
               ^^^^^^^^^^^^^^^^^^^^^^^^^^^^
  File "C:\Users\rakes\PycharmProjects\book_project\.venv\Lib\site-packages\flask\app.py", line 919, in full_dispatch_request
    rv = self.handle_user_exception(e)
         ^^^^^^^^^^^^^^^^^^^^^^^^^^^^^
  File "C:\Users\rakes\PycharmProjects\book_project\.venv\Lib\site-packages\flask\app.py", line 917, in full_dispatch_request
    rv = self.dispatch_request()
         ^^^^^^^^^^^^^^^^^^^^^^^
  File "C:\Users\rakes\PycharmProjects\book_project\.venv\Lib\site-packages\flask\app.py", line 902, in dispatch_request
    return self.ensure_sync(self.view_functions[rule.endpoint])(**view_args)  # type: ignore[no-any-return]
           ^^^^^^^^^^^^^^^^^^^^^^^^^^^^^^^^^^^^^^^^^^^^^^^^^^^^^^^^^^^^^^^^^
  File "C:\Users\rakes\PycharmProjects\book_project\.venv\Lib\site-packages\flask_login\utils.py", line 290, in decorated_view
    return current_app.ensure_sync(func)(*args, **kwargs)
           ^^^^^^^^^^^^^^^^^^^^^^^^^^^^^^^^^^^^^^^^^^^^^^
  File "C:\Users\rakes\PycharmProjects\book_project\app\routes\book_routes.py", line 79, in add_book
    return render_template('add_book.html')
           ^^^^^^^^^^^^^^^^^^^^^^^^^^^^^^^^
  File "C:\Users\rakes\PycharmProjects\book_project\.venv\Lib\site-packages\flask\templating.py", line 150, in render_template
    return _render(app, template, context)
           ^^^^^^^^^^^^^^^^^^^^^^^^^^^^^^^
  File "C:\Users\rakes\PycharmProjects\book_project\.venv\Lib\site-packages\flask\templating.py", line 131, in _render
    rv = template.render(context)
         ^^^^^^^^^^^^^^^^^^^^^^^^
  File "C:\Users\rakes\PycharmProjects\book_project\.venv\Lib\site-packages\jinja2\environment.py", line 1295, in render
    self.environment.handle_exception()
  File "C:\Users\rakes\PycharmProjects\book_project\.venv\Lib\site-packages\jinja2\environment.py", line 942, in handle_exception
    raise rewrite_traceback_stack(source=source)
  File "C:\Users\rakes\PycharmProjects\book_project\app\templates\add_book.html", line 1, in top-level template code
    {% extends 'base.html' %}
  File "C:\Users\rakes\PycharmProjects\book_project\app\templates\base.html", line 60, in top-level template code
    {% block content %}{% endblock %}
    ^^^^^^^^^^^^^^^^^^^^^^^^^
  File "C:\Users\rakes\PycharmProjects\book_project\app\templates\add_book.html", line 7, in block 'content'
    {{ form.hidden_tag() }}
  File "C:\Users\rakes\PycharmProjects\book_project\.venv\Lib\site-packages\jinja2\environment.py", line 490, in getattr
    return getattr(obj, attribute)
           ^^^^^^^^^^^^^^^^^^^^^^^
jinja2.exceptions.UndefinedError: 'form' is undefined
2025-04-19 10:12:23,244 INFO: BookApp startup [in C:\Users\rakes\PycharmProjects\book_project\app\__init__.py:65]
2025-04-19 10:18:54,022 INFO: BookApp startup [in C:\Users\rakes\PycharmProjects\book_project\app\__init__.py:65]
2025-04-19 10:23:32,955 INFO: BookApp startup [in C:\Users\rakes\PycharmProjects\book_project\app\__init__.py:65]
2025-04-19 10:24:24,088 ERROR: Exception on /auth/register [POST] [in C:\Users\rakes\PycharmProjects\book_project\.venv\Lib\site-packages\flask\app.py:875]
Traceback (most recent call last):
  File "C:\Users\rakes\PycharmProjects\book_project\.venv\Lib\site-packages\wtforms\validators.py", line 401, in __call__
    import email_validator
ModuleNotFoundError: No module named 'email_validator'

The above exception was the direct cause of the following exception:

Traceback (most recent call last):
  File "C:\Users\rakes\PycharmProjects\book_project\.venv\Lib\site-packages\flask\app.py", line 1511, in wsgi_app
    response = self.full_dispatch_request()
               ^^^^^^^^^^^^^^^^^^^^^^^^^^^^
  File "C:\Users\rakes\PycharmProjects\book_project\.venv\Lib\site-packages\flask\app.py", line 919, in full_dispatch_request
    rv = self.handle_user_exception(e)
         ^^^^^^^^^^^^^^^^^^^^^^^^^^^^^
  File "C:\Users\rakes\PycharmProjects\book_project\.venv\Lib\site-packages\flask\app.py", line 917, in full_dispatch_request
    rv = self.dispatch_request()
         ^^^^^^^^^^^^^^^^^^^^^^^
  File "C:\Users\rakes\PycharmProjects\book_project\.venv\Lib\site-packages\flask\app.py", line 902, in dispatch_request
    return self.ensure_sync(self.view_functions[rule.endpoint])(**view_args)  # type: ignore[no-any-return]
           ^^^^^^^^^^^^^^^^^^^^^^^^^^^^^^^^^^^^^^^^^^^^^^^^^^^^^^^^^^^^^^^^^
  File "C:\Users\rakes\PycharmProjects\book_project\app\routes\auth_routes.py", line 32, in register
    if form.validate_on_submit():
       ^^^^^^^^^^^^^^^^^^^^^^^^^
  File "C:\Users\rakes\PycharmProjects\book_project\.venv\Lib\site-packages\flask_wtf\form.py", line 86, in validate_on_submit
    return self.is_submitted() and self.validate(extra_validators=extra_validators)
                                   ^^^^^^^^^^^^^^^^^^^^^^^^^^^^^^^^^^^^^^^^^^^^^^^^
  File "C:\Users\rakes\PycharmProjects\book_project\.venv\Lib\site-packages\wtforms\form.py", line 330, in validate
    return super().validate(extra)
           ^^^^^^^^^^^^^^^^^^^^^^^
  File "C:\Users\rakes\PycharmProjects\book_project\.venv\Lib\site-packages\wtforms\form.py", line 147, in validate
    if not field.validate(self, extra):
           ^^^^^^^^^^^^^^^^^^^^^^^^^^^
  File "C:\Users\rakes\PycharmProjects\book_project\.venv\Lib\site-packages\wtforms\fields\core.py", line 234, in validate
    stop_validation = self._run_validation_chain(form, chain)
                      ^^^^^^^^^^^^^^^^^^^^^^^^^^^^^^^^^^^^^^^
  File "C:\Users\rakes\PycharmProjects\book_project\.venv\Lib\site-packages\wtforms\fields\core.py", line 254, in _run_validation_chain
    validator(form, self)
  File "C:\Users\rakes\PycharmProjects\book_project\.venv\Lib\site-packages\wtforms\validators.py", line 403, in __call__
    raise Exception(
Exception: Install 'email_validator' for email validation support.
2025-04-19 10:27:29,205 INFO: BookApp startup [in C:\Users\rakes\PycharmProjects\book_project\app\__init__.py:65]
2025-04-19 10:27:44,788 ERROR: Exception on /auth/register [POST] [in C:\Users\rakes\PycharmProjects\book_project\.venv\Lib\site-packages\flask\app.py:875]
Traceback (most recent call last):
  File "C:\Users\rakes\PycharmProjects\book_project\.venv\Lib\site-packages\sqlalchemy\sql\base.py", line 2181, in _entity_namespace_key
    return getattr(ns, key)  # type: ignore
           ^^^^^^^^^^^^^^^^
AttributeError: type object 'User' has no attribute 'email'

The above exception was the direct cause of the following exception:

Traceback (most recent call last):
  File "C:\Users\rakes\PycharmProjects\book_project\.venv\Lib\site-packages\flask\app.py", line 1511, in wsgi_app
    response = self.full_dispatch_request()
               ^^^^^^^^^^^^^^^^^^^^^^^^^^^^
  File "C:\Users\rakes\PycharmProjects\book_project\.venv\Lib\site-packages\flask\app.py", line 919, in full_dispatch_request
    rv = self.handle_user_exception(e)
         ^^^^^^^^^^^^^^^^^^^^^^^^^^^^^
  File "C:\Users\rakes\PycharmProjects\book_project\.venv\Lib\site-packages\flask\app.py", line 917, in full_dispatch_request
    rv = self.dispatch_request()
         ^^^^^^^^^^^^^^^^^^^^^^^
  File "C:\Users\rakes\PycharmProjects\book_project\.venv\Lib\site-packages\flask\app.py", line 902, in dispatch_request
    return self.ensure_sync(self.view_functions[rule.endpoint])(**view_args)  # type: ignore[no-any-return]
           ^^^^^^^^^^^^^^^^^^^^^^^^^^^^^^^^^^^^^^^^^^^^^^^^^^^^^^^^^^^^^^^^^
  File "C:\Users\rakes\PycharmProjects\book_project\app\routes\auth_routes.py", line 32, in register
    if form.validate_on_submit():
       ^^^^^^^^^^^^^^^^^^^^^^^^^
  File "C:\Users\rakes\PycharmProjects\book_project\.venv\Lib\site-packages\flask_wtf\form.py", line 86, in validate_on_submit
    return self.is_submitted() and self.validate(extra_validators=extra_validators)
                                   ^^^^^^^^^^^^^^^^^^^^^^^^^^^^^^^^^^^^^^^^^^^^^^^^
  File "C:\Users\rakes\PycharmProjects\book_project\.venv\Lib\site-packages\wtforms\form.py", line 330, in validate
    return super().validate(extra)
           ^^^^^^^^^^^^^^^^^^^^^^^
  File "C:\Users\rakes\PycharmProjects\book_project\.venv\Lib\site-packages\wtforms\form.py", line 147, in validate
    if not field.validate(self, extra):
           ^^^^^^^^^^^^^^^^^^^^^^^^^^^
  File "C:\Users\rakes\PycharmProjects\book_project\.venv\Lib\site-packages\wtforms\fields\core.py", line 234, in validate
    stop_validation = self._run_validation_chain(form, chain)
                      ^^^^^^^^^^^^^^^^^^^^^^^^^^^^^^^^^^^^^^^
  File "C:\Users\rakes\PycharmProjects\book_project\.venv\Lib\site-packages\wtforms\fields\core.py", line 254, in _run_validation_chain
    validator(form, self)
  File "C:\Users\rakes\PycharmProjects\book_project\app\models\forms.py", line 27, in validate_email
    if User.query.filter_by(email=email.data).first():
       ^^^^^^^^^^^^^^^^^^^^^^^^^^^^^^^^^^^^^^
  File "C:\Users\rakes\PycharmProjects\book_project\.venv\Lib\site-packages\sqlalchemy\orm\query.py", line 1992, in filter_by
    _entity_namespace_key(from_entity, key) == value
    ^^^^^^^^^^^^^^^^^^^^^^^^^^^^^^^^^^^^^^^
  File "C:\Users\rakes\PycharmProjects\book_project\.venv\Lib\site-packages\sqlalchemy\sql\base.py", line 2183, in _entity_namespace_key
    raise exc.InvalidRequestError(
sqlalchemy.exc.InvalidRequestError: Entity namespace for "user" has no property "email"
2025-04-19 10:41:38,779 INFO: BookApp startup [in C:\Users\rakes\PycharmProjects\book_project\app\__init__.py:65]
2025-04-19 10:41:59,206 INFO: BookApp startup [in C:\Users\rakes\PycharmProjects\book_project\app\__init__.py:65]
2025-04-19 10:46:05,417 INFO: BookApp startup [in C:\Users\rakes\PycharmProjects\book_project\app\__init__.py:65]
2025-04-19 10:46:22,860 INFO: BookApp startup [in C:\Users\rakes\PycharmProjects\book_project\app\__init__.py:65]
2025-04-19 10:48:06,648 INFO: BookApp startup [in C:\Users\rakes\PycharmProjects\book_project\app\__init__.py:65]
2025-04-19 10:48:09,273 INFO: BookApp startup [in C:\Users\rakes\PycharmProjects\book_project\app\__init__.py:65]
2025-04-19 10:50:11,337 INFO: BookApp startup [in C:\Users\rakes\PycharmProjects\book_project\app\__init__.py:65]
2025-04-19 10:50:24,861 INFO: BookApp startup [in C:\Users\rakes\PycharmProjects\book_project\app\__init__.py:65]
2025-04-19 10:50:35,282 INFO: BookApp startup [in C:\Users\rakes\PycharmProjects\book_project\app\__init__.py:65]
2025-04-19 11:23:04,546 INFO: BookApp startup [in C:\Users\rakes\PycharmProjects\book_project\app\__init__.py:65]
2025-04-19 11:23:17,785 ERROR: Exception on /auth/login [POST] [in C:\Users\rakes\PycharmProjects\book_project\.venv\Lib\site-packages\flask\app.py:875]
Traceback (most recent call last):
  File "C:\Users\rakes\PycharmProjects\book_project\.venv\Lib\site-packages\sqlalchemy\engine\base.py", line 1964, in _exec_single_context
    self.dialect.do_execute(
  File "C:\Users\rakes\PycharmProjects\book_project\.venv\Lib\site-packages\sqlalchemy\engine\default.py", line 945, in do_execute
    cursor.execute(statement, parameters)
sqlite3.OperationalError: no such column: user.email

The above exception was the direct cause of the following exception:

Traceback (most recent call last):
  File "C:\Users\rakes\PycharmProjects\book_project\.venv\Lib\site-packages\flask\app.py", line 1511, in wsgi_app
    response = self.full_dispatch_request()
               ^^^^^^^^^^^^^^^^^^^^^^^^^^^^
  File "C:\Users\rakes\PycharmProjects\book_project\.venv\Lib\site-packages\flask\app.py", line 919, in full_dispatch_request
    rv = self.handle_user_exception(e)
         ^^^^^^^^^^^^^^^^^^^^^^^^^^^^^
  File "C:\Users\rakes\PycharmProjects\book_project\.venv\Lib\site-packages\flask\app.py", line 917, in full_dispatch_request
    rv = self.dispatch_request()
         ^^^^^^^^^^^^^^^^^^^^^^^
  File "C:\Users\rakes\PycharmProjects\book_project\.venv\Lib\site-packages\flask\app.py", line 902, in dispatch_request
    return self.ensure_sync(self.view_functions[rule.endpoint])(**view_args)  # type: ignore[no-any-return]
           ^^^^^^^^^^^^^^^^^^^^^^^^^^^^^^^^^^^^^^^^^^^^^^^^^^^^^^^^^^^^^^^^^
  File "C:\Users\rakes\PycharmProjects\book_project\app\routes\auth_routes.py", line 16, in login
    user = User.query.filter_by(username=username).first()
           ^^^^^^^^^^^^^^^^^^^^^^^^^^^^^^^^^^^^^^^^^^^^^^^
  File "C:\Users\rakes\PycharmProjects\book_project\.venv\Lib\site-packages\sqlalchemy\orm\query.py", line 2759, in first
    return self.limit(1)._iter().first()  # type: ignore
           ^^^^^^^^^^^^^^^^^^^^^
  File "C:\Users\rakes\PycharmProjects\book_project\.venv\Lib\site-packages\sqlalchemy\orm\query.py", line 2858, in _iter
    result: Union[ScalarResult[_T], Result[_T]] = self.session.execute(
                                                  ^^^^^^^^^^^^^^^^^^^^^
  File "C:\Users\rakes\PycharmProjects\book_project\.venv\Lib\site-packages\sqlalchemy\orm\session.py", line 2365, in execute
    return self._execute_internal(
           ^^^^^^^^^^^^^^^^^^^^^^^
  File "C:\Users\rakes\PycharmProjects\book_project\.venv\Lib\site-packages\sqlalchemy\orm\session.py", line 2251, in _execute_internal
    result: Result[Any] = compile_state_cls.orm_execute_statement(
                          ^^^^^^^^^^^^^^^^^^^^^^^^^^^^^^^^^^^^^^^^
  File "C:\Users\rakes\PycharmProjects\book_project\.venv\Lib\site-packages\sqlalchemy\orm\context.py", line 306, in orm_execute_statement
    result = conn.execute(
             ^^^^^^^^^^^^^
  File "C:\Users\rakes\PycharmProjects\book_project\.venv\Lib\site-packages\sqlalchemy\engine\base.py", line 1416, in execute
    return meth(
           ^^^^^
  File "C:\Users\rakes\PycharmProjects\book_project\.venv\Lib\site-packages\sqlalchemy\sql\elements.py", line 523, in _execute_on_connection
    return connection._execute_clauseelement(
           ^^^^^^^^^^^^^^^^^^^^^^^^^^^^^^^^^^
  File "C:\Users\rakes\PycharmProjects\book_project\.venv\Lib\site-packages\sqlalchemy\engine\base.py", line 1638, in _execute_clauseelement
    ret = self._execute_context(
          ^^^^^^^^^^^^^^^^^^^^^^
  File "C:\Users\rakes\PycharmProjects\book_project\.venv\Lib\site-packages\sqlalchemy\engine\base.py", line 1843, in _execute_context
    return self._exec_single_context(
           ^^^^^^^^^^^^^^^^^^^^^^^^^^
  File "C:\Users\rakes\PycharmProjects\book_project\.venv\Lib\site-packages\sqlalchemy\engine\base.py", line 1983, in _exec_single_context
    self._handle_dbapi_exception(
  File "C:\Users\rakes\PycharmProjects\book_project\.venv\Lib\site-packages\sqlalchemy\engine\base.py", line 2352, in _handle_dbapi_exception
    raise sqlalchemy_exception.with_traceback(exc_info[2]) from e
  File "C:\Users\rakes\PycharmProjects\book_project\.venv\Lib\site-packages\sqlalchemy\engine\base.py", line 1964, in _exec_single_context
    self.dialect.do_execute(
  File "C:\Users\rakes\PycharmProjects\book_project\.venv\Lib\site-packages\sqlalchemy\engine\default.py", line 945, in do_execute
    cursor.execute(statement, parameters)
sqlalchemy.exc.OperationalError: (sqlite3.OperationalError) no such column: user.email
[SQL: SELECT user.id AS user_id, user.username AS user_username, user.email AS user_email, user.password_hash AS user_password_hash, user.is_admin AS user_is_admin, user.created_at AS user_created_at 
FROM user 
WHERE user.username = ?
 LIMIT ? OFFSET ?]
[parameters: ('admin', 1, 0)]
(Background on this error at: https://sqlalche.me/e/20/e3q8)
2025-04-19 22:26:12,931 INFO: BookApp startup [in C:\Users\rakes\PycharmProjects\book_project\app\__init__.py:65]
2025-04-19 22:28:00,429 INFO: BookApp startup [in C:\Users\rakes\PycharmProjects\book_project\app\__init__.py:65]
2025-04-19 22:28:13,973 INFO: BookApp startup [in C:\Users\rakes\PycharmProjects\book_project\app\__init__.py:65]
2025-04-19 22:28:27,091 INFO: BookApp startup [in C:\Users\rakes\PycharmProjects\book_project\app\__init__.py:65]
2025-04-19 22:28:44,360 INFO: BookApp startup [in C:\Users\rakes\PycharmProjects\book_project\app\__init__.py:65]
2025-04-19 22:29:41,982 ERROR: Exception on /auth/register [POST] [in C:\Users\rakes\PycharmProjects\book_project\.venv\Lib\site-packages\flask\app.py:875]
Traceback (most recent call last):
  File "C:\Users\rakes\PycharmProjects\book_project\.venv\Lib\site-packages\flask\app.py", line 1511, in wsgi_app
    response = self.full_dispatch_request()
               ^^^^^^^^^^^^^^^^^^^^^^^^^^^^
  File "C:\Users\rakes\PycharmProjects\book_project\.venv\Lib\site-packages\flask\app.py", line 919, in full_dispatch_request
    rv = self.handle_user_exception(e)
         ^^^^^^^^^^^^^^^^^^^^^^^^^^^^^
  File "C:\Users\rakes\PycharmProjects\book_project\.venv\Lib\site-packages\flask\app.py", line 917, in full_dispatch_request
    rv = self.dispatch_request()
         ^^^^^^^^^^^^^^^^^^^^^^^
  File "C:\Users\rakes\PycharmProjects\book_project\.venv\Lib\site-packages\flask\app.py", line 902, in dispatch_request
    return self.ensure_sync(self.view_functions[rule.endpoint])(**view_args)  # type: ignore[no-any-return]
           ^^^^^^^^^^^^^^^^^^^^^^^^^^^^^^^^^^^^^^^^^^^^^^^^^^^^^^^^^^^^^^^^^
  File "C:\Users\rakes\PycharmProjects\book_project\app\routes\auth_routes.py", line 41, in register
    new_user = User(username=form.username.data, password=hashed_password, is_admin=False)
               ^^^^^^^^^^^^^^^^^^^^^^^^^^^^^^^^^^^^^^^^^^^^^^^^^^^^^^^^^^^^^^^^^^^^^^^^^^^
  File "<string>", line 4, in __init__
  File "C:\Users\rakes\PycharmProjects\book_project\.venv\Lib\site-packages\sqlalchemy\orm\state.py", line 571, in _initialize_instance
    with util.safe_reraise():
  File "C:\Users\rakes\PycharmProjects\book_project\.venv\Lib\site-packages\sqlalchemy\util\langhelpers.py", line 146, in __exit__
    raise exc_value.with_traceback(exc_tb)
  File "C:\Users\rakes\PycharmProjects\book_project\.venv\Lib\site-packages\sqlalchemy\orm\state.py", line 569, in _initialize_instance
    manager.original_init(*mixed[1:], **kwargs)
  File "C:\Users\rakes\PycharmProjects\book_project\.venv\Lib\site-packages\sqlalchemy\orm\decl_base.py", line 2175, in _declarative_constructor
    raise TypeError(
TypeError: 'password' is an invalid keyword argument for User
2025-04-19 22:30:18,040 ERROR: Exception on /auth/register [POST] [in C:\Users\rakes\PycharmProjects\book_project\.venv\Lib\site-packages\flask\app.py:875]
Traceback (most recent call last):
  File "C:\Users\rakes\PycharmProjects\book_project\.venv\Lib\site-packages\flask\app.py", line 1511, in wsgi_app
    response = self.full_dispatch_request()
               ^^^^^^^^^^^^^^^^^^^^^^^^^^^^
  File "C:\Users\rakes\PycharmProjects\book_project\.venv\Lib\site-packages\flask\app.py", line 919, in full_dispatch_request
    rv = self.handle_user_exception(e)
         ^^^^^^^^^^^^^^^^^^^^^^^^^^^^^
  File "C:\Users\rakes\PycharmProjects\book_project\.venv\Lib\site-packages\flask\app.py", line 917, in full_dispatch_request
    rv = self.dispatch_request()
         ^^^^^^^^^^^^^^^^^^^^^^^
  File "C:\Users\rakes\PycharmProjects\book_project\.venv\Lib\site-packages\flask\app.py", line 902, in dispatch_request
    return self.ensure_sync(self.view_functions[rule.endpoint])(**view_args)  # type: ignore[no-any-return]
           ^^^^^^^^^^^^^^^^^^^^^^^^^^^^^^^^^^^^^^^^^^^^^^^^^^^^^^^^^^^^^^^^^
  File "C:\Users\rakes\PycharmProjects\book_project\app\routes\auth_routes.py", line 41, in register
    new_user = User(username=form.username.data, password=hashed_password, is_admin=False)
               ^^^^^^^^^^^^^^^^^^^^^^^^^^^^^^^^^^^^^^^^^^^^^^^^^^^^^^^^^^^^^^^^^^^^^^^^^^^
  File "<string>", line 4, in __init__
  File "C:\Users\rakes\PycharmProjects\book_project\.venv\Lib\site-packages\sqlalchemy\orm\state.py", line 571, in _initialize_instance
    with util.safe_reraise():
  File "C:\Users\rakes\PycharmProjects\book_project\.venv\Lib\site-packages\sqlalchemy\util\langhelpers.py", line 146, in __exit__
    raise exc_value.with_traceback(exc_tb)
  File "C:\Users\rakes\PycharmProjects\book_project\.venv\Lib\site-packages\sqlalchemy\orm\state.py", line 569, in _initialize_instance
    manager.original_init(*mixed[1:], **kwargs)
  File "C:\Users\rakes\PycharmProjects\book_project\.venv\Lib\site-packages\sqlalchemy\orm\decl_base.py", line 2175, in _declarative_constructor
    raise TypeError(
TypeError: 'password' is an invalid keyword argument for User
2025-04-19 22:31:54,385 INFO: BookApp startup [in C:\Users\rakes\PycharmProjects\book_project\app\__init__.py:65]
2025-04-19 22:33:19,775 INFO: BookApp startup [in C:\Users\rakes\PycharmProjects\book_project\app\__init__.py:65]
2025-04-19 22:34:59,674 ERROR: Exception on /auth/register [POST] [in C:\Users\rakes\PycharmProjects\book_project\.venv\Lib\site-packages\flask\app.py:875]
Traceback (most recent call last):
  File "C:\Users\rakes\PycharmProjects\book_project\.venv\Lib\site-packages\flask\app.py", line 1511, in wsgi_app
    response = self.full_dispatch_request()
               ^^^^^^^^^^^^^^^^^^^^^^^^^^^^
  File "C:\Users\rakes\PycharmProjects\book_project\.venv\Lib\site-packages\flask\app.py", line 919, in full_dispatch_request
    rv = self.handle_user_exception(e)
         ^^^^^^^^^^^^^^^^^^^^^^^^^^^^^
  File "C:\Users\rakes\PycharmProjects\book_project\.venv\Lib\site-packages\flask\app.py", line 917, in full_dispatch_request
    rv = self.dispatch_request()
         ^^^^^^^^^^^^^^^^^^^^^^^
  File "C:\Users\rakes\PycharmProjects\book_project\.venv\Lib\site-packages\flask\app.py", line 902, in dispatch_request
    return self.ensure_sync(self.view_functions[rule.endpoint])(**view_args)  # type: ignore[no-any-return]
           ^^^^^^^^^^^^^^^^^^^^^^^^^^^^^^^^^^^^^^^^^^^^^^^^^^^^^^^^^^^^^^^^^
  File "C:\Users\rakes\PycharmProjects\book_project\app\routes\auth_routes.py", line 41, in register
    new_user = User(username=form.username.data, password=hashed_password, is_admin=False)
               ^^^^^^^^^^^^^^^^^^^^^^^^^^^^^^^^^^^^^^^^^^^^^^^^^^^^^^^^^^^^^^^^^^^^^^^^^^^
  File "<string>", line 4, in __init__
  File "C:\Users\rakes\PycharmProjects\book_project\.venv\Lib\site-packages\sqlalchemy\orm\state.py", line 571, in _initialize_instance
    with util.safe_reraise():
  File "C:\Users\rakes\PycharmProjects\book_project\.venv\Lib\site-packages\sqlalchemy\util\langhelpers.py", line 146, in __exit__
    raise exc_value.with_traceback(exc_tb)
  File "C:\Users\rakes\PycharmProjects\book_project\.venv\Lib\site-packages\sqlalchemy\orm\state.py", line 569, in _initialize_instance
    manager.original_init(*mixed[1:], **kwargs)
  File "C:\Users\rakes\PycharmProjects\book_project\.venv\Lib\site-packages\sqlalchemy\orm\decl_base.py", line 2175, in _declarative_constructor
    raise TypeError(
TypeError: 'password' is an invalid keyword argument for User
2025-04-19 22:40:26,333 INFO: BookApp startup [in C:\Users\rakes\PycharmProjects\book_project\app\__init__.py:65]
2025-04-19 22:43:21,575 ERROR: Exception on /books/edit/3 [GET] [in C:\Users\rakes\PycharmProjects\book_project\.venv\Lib\site-packages\flask\app.py:875]
Traceback (most recent call last):
  File "C:\Users\rakes\PycharmProjects\book_project\.venv\Lib\site-packages\flask\app.py", line 1511, in wsgi_app
    response = self.full_dispatch_request()
               ^^^^^^^^^^^^^^^^^^^^^^^^^^^^
  File "C:\Users\rakes\PycharmProjects\book_project\.venv\Lib\site-packages\flask\app.py", line 919, in full_dispatch_request
    rv = self.handle_user_exception(e)
         ^^^^^^^^^^^^^^^^^^^^^^^^^^^^^
  File "C:\Users\rakes\PycharmProjects\book_project\.venv\Lib\site-packages\flask\app.py", line 917, in full_dispatch_request
    rv = self.dispatch_request()
         ^^^^^^^^^^^^^^^^^^^^^^^
  File "C:\Users\rakes\PycharmProjects\book_project\.venv\Lib\site-packages\flask\app.py", line 902, in dispatch_request
    return self.ensure_sync(self.view_functions[rule.endpoint])(**view_args)  # type: ignore[no-any-return]
           ^^^^^^^^^^^^^^^^^^^^^^^^^^^^^^^^^^^^^^^^^^^^^^^^^^^^^^^^^^^^^^^^^
  File "C:\Users\rakes\PycharmProjects\book_project\.venv\Lib\site-packages\flask_login\utils.py", line 290, in decorated_view
    return current_app.ensure_sync(func)(*args, **kwargs)
           ^^^^^^^^^^^^^^^^^^^^^^^^^^^^^^^^^^^^^^^^^^^^^^
  File "C:\Users\rakes\PycharmProjects\book_project\app\routes\book_routes.py", line 95, in edit
    return render_template('edit_book.html', book=book)
           ^^^^^^^^^^^^^^^^^^^^^^^^^^^^^^^^^^^^^^^^^^^^
  File "C:\Users\rakes\PycharmProjects\book_project\.venv\Lib\site-packages\flask\templating.py", line 150, in render_template
    return _render(app, template, context)
           ^^^^^^^^^^^^^^^^^^^^^^^^^^^^^^^
  File "C:\Users\rakes\PycharmProjects\book_project\.venv\Lib\site-packages\flask\templating.py", line 131, in _render
    rv = template.render(context)
         ^^^^^^^^^^^^^^^^^^^^^^^^
  File "C:\Users\rakes\PycharmProjects\book_project\.venv\Lib\site-packages\jinja2\environment.py", line 1295, in render
    self.environment.handle_exception()
  File "C:\Users\rakes\PycharmProjects\book_project\.venv\Lib\site-packages\jinja2\environment.py", line 942, in handle_exception
    raise rewrite_traceback_stack(source=source)
  File "C:\Users\rakes\PycharmProjects\book_project\app\templates\edit_book.html", line 1, in top-level template code
    {% extends 'base.html' %}
  File "C:\Users\rakes\PycharmProjects\book_project\app\templates\base.html", line 60, in top-level template code
    {% block content %}{% endblock %}
    ^^^^^^^^^^^^^^^^^^^^^^^^^
  File "C:\Users\rakes\PycharmProjects\book_project\app\templates\edit_book.html", line 7, in block 'content'
    {{ form.hidden_tag() }}
  File "C:\Users\rakes\PycharmProjects\book_project\.venv\Lib\site-packages\jinja2\environment.py", line 490, in getattr
    return getattr(obj, attribute)
           ^^^^^^^^^^^^^^^^^^^^^^^
jinja2.exceptions.UndefinedError: 'form' is undefined
2025-04-19 22:47:00,258 INFO: BookApp startup [in C:\Users\rakes\PycharmProjects\book_project\app\__init__.py:65]
2025-04-19 22:56:30,689 INFO: BookApp startup [in C:\Users\rakes\PycharmProjects\book_project\app\__init__.py:65]
2025-04-19 23:01:09,489 INFO: BookApp startup [in C:\Users\rakes\PycharmProjects\book_project\app\__init__.py:65]
2025-04-19 23:02:24,903 INFO: BookApp startup [in C:\Users\rakes\PycharmProjects\book_project\app\__init__.py:65]
